Workbook

Sheet Horas
A1: Parte 2026-2027 | B1: 0.33333333 | C1: 0.29166667
B2: Mayo - 25 | C2: Junio - 25 | D2: Julio - 25 | E2: Agosto 25 | F2: Septiembre - 25 | G2: Octubre - 25 | H2: Noviembre - 25 | I2: Diciembre -25 | J2: Enero - 26 | K2: Febrero - 26 | L2: Marzo - 26 | M2: Abril - 26 | N2: Mayo - 26 | O2: Vacaciones
A3: Días | B3: =B13+C13 -> 4 | C3: =B14+C14 -> 22 | D3: =B15+C15 -> 23 | E3: =B16+C16 -> 21 | F3: =B17+C17 -> 22 | G3: =B18+C18 -> 21 | H3: =B19+C19 -> 19 | I3: =B20+C20 -> 18 | J3: =B21+C21 -> 19 | K3: =B22+C22 -> 20 | L3: =B23+C23 -> 20 | M3: =B24+C24 -> 22 | N3: =B25+C25 -> 17 | O3: 23 | P3: =O3*B1 -> 7.6666667
A4: Días Vacaciones 8h | B4: ='Mayo 26'!C53 -> 0 | C4: =Junio!C53 -> 0 | D4: 0 | E4: 0 | F4: =Septiembre!C53 -> 0 | G4: =Octubre!C53 -> 0 | H4: =Noviembre!C53 -> 0 | I4: =Diciembre!C53 -> 0 | J4: =Enero!C53 -> 0 | K4: =Febrero!C53 -> 0 | L4: =Marzo!C53 -> 0 | M4: =Abril!C53 -> 0 | N4: =Mayo!C53 -> 0 | O4: =SUM(B4:N4) -> 0
A5: Días Vacaciones 7h | B5: 0 | C5: =Junio!C54 -> 0 | D5: =Julio!C53 -> 1 | E5: =Agosto!C53 -> 12 | F5: =Septiembre!C54 -> 0 | G5: 0 | H5: 0 | I5: 0 | J5: 0 | K5: 0 | L5: 0 | M5: 0 | N5: 0 | O5: =SUM(B5:N5) -> 13 | P5: =SUM(O4:O5,P4) -> 13
A6: Horas Vacaciones | B6: =B4*$B1+B5*$C1 -> 0 | C6: =C4*$B1+C5*$C1 -> 0 | D6: =D4*$B1+D5*$C1 -> 0.29166667 | E6: =E4*$B1+E5*$C1 -> 3.5 | F6: =F4*$B1+F5*$C1 -> 0 | G6: =G4*$B1+G5*$C1 -> 0 | H6: =H4*$B1+H5*$C1 -> 0 | I6: =I4*$B1+I5*$C1 -> 0 | ... N6: =N4*$B1+N5*$C1 -> 0 | O6: =SUM(B6:N6) -> 3.7916667
A7: Horas Mes | B7: =B3*B1 -> 1.3333333 | C7: =B14*$B1+C14*$C1 -> 6.8333333 | D7: =D3*$C1 -> 6.7083333 | E7: =E3*$C1 -> 6.125 | F7: =B17*$B1+C17*$C1 -> 6.875 | G7: =G3*$B1 -> 7 | H7: =H3*$B1 -> 6.3333333 | I7: =I3*$B1 -> 6 | J7: =J3*$B1 -> 6.3333333 | K7: =K3*$B1 -> 6.6666667 | L7: =L3*$B1 -> 6.6666667 | M7: =M3*$B1 -> 7.3333333 | N7: =N3*$B1 -> 5.6666667 | O7: =SUM(B7:N7) -> 79.875 | P7: =O7-Q8 -> 6.5416667 | Q7: =P7-O6 -> 2.75
A8: Horas Realizadas | B8: ='Mayo 26'!$C$47 -> 1.3958333 | C8: =Junio!$C$47 -> 6.9166667 | D8: =Julio!$C$47 -> 6.6256944 | E8: =Agosto!$C$47 -> 2.65625 | F8: =Septiembre!$C$47 -> 6.8972222 | G8: =Octubre!$C$47 -> 7.0208333 | H8: =Noviembre!$C$47 -> 6.3541667 | I8: =Diciembre!$C$47 -> 6.0208333 | J8: =Enero!$C$47 -> 6.3541667 | K8: =Febrero!$C$47 -> 6.6875 | L8: =Marzo!$C$47 -> 6.6979167 | M8: =Abril!$C$47 -> 7.3541667 | N8: =Mayo!$C$47 -> 5.71875 | O8: =SUM(B8:N8) -> 76.7 | P8: =O8-Q8 -> 3.3666667 | Q8: 73.333333
A9: Horas Sobrantes | B9: =IF(B8+B6>=B7,B8+B6-B7,B7-B6-B8) -> 0.0625 | C9: =IF(C8+C6>=C7,C8+C6-C7,C7-C6-C8) -> 0.083333333 | D9: =IF(D8+D6>=D7,D8+D6-D7,D7-D6-D8) -> 0.20902778 | E9: =E8+E6-E7 -> 0.03125 | F9: =IF(F8+F6>=F7,F8+F6-F7,F7-F6-F8) -> 0.022222222 | G9: =IF(G8+G6>=G7,G8+G6-G7,G7-G6-G8) -> 0.020833333 | H9: =IF(H8+H6>=H7,H8+H6-H7,H7-H6-H8) -> 0.020833333 | I9: =IF(I8+I6>=I7,I8+I6-I7,I7-I6-I8) -> 0.020833333 | J9: =IF(J8+J6>=J7,J8+J6-J7,J7-J6-J8) -> 0.020833333 | K9: =IF(K8+K6>=K7,K8+K6-K7,K7-K6-K8) -> 0.020833333 | L9: =IF(L8+L6>=L7,L8+L6-L7,L7-L6-L8) -> 0.03125 | M9: =IF(M8+M6>=M7,M8+M6-M7,M7-M6-M8) -> 0.020833333 | N9: =IF(N8+N6>=N7,N8+N6-N7,N7-N6-N8) -> 0.052083333 | P9: =10*8 -> 80
B12: Días 8h | C12: Días 7h | D12: Horas
A13: Mayo | B13: 4 | C13: 0 | D13: =B13*B1 -> 1.3333333
A14: Junio | B14: 10 | C14: 12 | D14: =B14*B1+C14*C1 -> 6.8333333
A15: Julio | B15: 0 | C15: 23 | D15: =C15*C1 -> 6.7083333
A16: Agosto | B16: 0 | C16: 21 | D16: =C16*C1 -> 6.125
A17: Septiembre | B17: 11 | C17: 11 | D17: =B17*B1+C17*C1 -> 6.875
A18: Octubre | B18: 21 | C18: 0 | D18: =B18*B1 -> 7
A19: Noviembre | B19: 19 | C19: 0 | D19: =B19*$B$1 -> 6.3333333
A20: Diciembre | B20: 18 | C20: 0 | D20: =B20*$B$1 -> 6
A21: Enero | B21: 19 | C21: 0 | D21: =B21*$B$1 -> 6.3333333
A22: Febrero | B22: 20 | C22: 0 | D22: =B22*$B$1 -> 6.6666667
A23: Marzo | B23: 20 | C23: 0 | D23: =B23*$B$1 -> 6.6666667
A24: Abril | B24: 22 | C24: 0 | D24: =B24*$B$1 -> 7.3333333
A25: Mayo | B25: 17 | C25: 0 | D25: =B25*$B$1 -> 5.6666667
B26: =SUM(B13:B25,C13:C25) -> 248 | C26: TOTAL | D26: =SUM(D13:D25) -> 79.875
C27: Sobrante | D27: =D26-Q8 -> 6.5416667
C28: Vacaciones (23) | D28: =23*B1 -> 7.6666667 | E28: =12*C1+11*B1 -> 7.1666667
C29: Recuperar | D29: =D28-D27 -> 1.125 | E29: =E28-D27 -> 0.625
B32: 33.5 | C32: 166 | D32: 159 | E32: 63.75 | F32: 165.5 | G32: 168.5 | H32: 152.5 | I32: 144.5 | J32: 152.5 | K32: 160.5 | L32: 160.75 | M32: 176.5 | N32: 137.25 | O32: =SUM(B32:N32) -> 1840.75
O33: =O32-1760 -> 80.75

Sheet Mayo 26
A1: Empresa: | B1: IZERTIS | E1: Tiempo min comida | F1: 0.020833333 | I1: Dias Mes: | J1: 4
A2: Nombre: | E2: Tiempo desayuno | F2: 0.013888889 | I2: Horas / Día: | J2: 0.33333333
A3: Mes: | B3: 46143 | E3: % R.Domic. | F3: 50 | I3: Días R.Dom: | J3: 8
N4: Teletrabajo tardes MIXTO
A5: Día | B5: ENTRADA | C5: Salida Desay | D5: Entrada Desay | E5: Salida Comida | F5: Entrada Comida | G5: Hora Salida | H5: Hora Entrada | I5: SALIDA | J5: Total Comida | K5: Total Desayuno | L5: Total Día | M5: Ubic | N5: Entrada Comida | O5: SALIDA | T5: =C46 -> 1.3333333 | V5: JIRA | W5: Día | Y5: CONTROL TELETRABAJO | AC5: IZERTIA | AD5: IZERTIA/JIRA
Q6: 1 | Y6: OFICINA | Z6: CASA | AA6: MIXTA T. | AB6: Total
P7: =MROUND(L7,"0:15") -> 0 | Q7: =VALUE(MID(TEXT(L7,"hh:mm:ss"),4,2)+Q6)-IF(ABS((MID(TEXT(L7,"hh:mm:ss"),4,2)+Q6)-FLOOR((MID(TEXT(L7,"hh:mm:ss"),4,2)+Q6),15))>ABS((MID(TEXT(L7,"hh:mm:ss"),4,2)+Q6)-CEILING((MID(TEXT(L7,"hh:mm:ss"),4,2)+Q6),15)),CEILING((MID(TEXT(L7,"hh:mm:ss"),4,2)+Q6),15),FLOOR((MID(TEXT(L7,"hh:mm:ss"),4,2)+Q6),15)) -> 1 | T7: =T5-L7 -> 1.3333333 | V7: 0 | Y7: =IF(O7="O",V7 - AA7,"0:00:00") -> 0:00:00 | Z7: =IF(M7="C",P7,"0:00:00") -> 0:00:00 | AA7: =IF(P7="M",Q7-P7,"0:00:00") -> 0:00:00 | AB7: =SUM(Y7:Z7) -> 0 | AC7: 0
P8: =MROUND(L8,"0:15") -> 0 | Q8: =VALUE(MID(TEXT(L8,"hh:mm:ss"),4,2)+Q7)-IF(ABS((MID(TEXT(L8,"hh:mm:ss"),4,2)+Q7)-FLOOR((MID(TEXT(L8,"hh:mm:ss"),4,2)+Q7),15))>ABS((MID(TEXT(L8,"hh:mm:ss"),4,2)+Q7)-CEILING((MID(TEXT(L8,"hh:mm:ss"),4,2)+Q7),15)),CEILING((MID(TEXT(L8,"hh:mm:ss"),4,2)+Q7),15),FLOOR((MID(TEXT(L8,"hh:mm:ss"),4,2)+Q7),15)) -> 1 | T8: =T7-L8 -> 1.3333333 | V8: 0 | Y8: =IF(M8="O",P8 - AA8,"0:00:00") -> 0:00:00 | Z8: =IF(M8="C",P8,"0:00:00") -> 0:00:00 | AA8: 0 | AB8: =SUM(Y8:Z8) -> 0 | AC8: 0
M9: O | P9: =MROUND(L9,"0:15") -> 0 | Q9: =VALUE(MID(TEXT(L9,"hh:mm:ss"),4,2)+Q8)-IF(ABS((MID(TEXT(L9,"hh:mm:ss"),4,2)+Q8)-FLOOR((MID(TEXT(L9,"hh:mm:ss"),4,2)+Q8),15))>ABS((MID(TEXT(L9,"hh:mm:ss"),4,2)+Q8)-CEILING((MID(TEXT(L9,"hh:mm:ss"),4,2)+Q8),15)),CEILING((MID(TEXT(L9,"hh:mm:ss"),4,2)+Q8),15),FLOOR((MID(TEXT(L9,"hh:mm:ss"),4,2)+Q8),15)) -> 1 | T9: =T8-L9 -> 1.3333333 | V9: 0 | Y9: =IF(M9="O",P9 - AA9,"0:00:00") -> 0 | Z9: =IF(M9="C",P9,"0:00:00") -> 0:00:00 | AA9: =IF(P9="M",Q9-P9,"0:00:00") -> 0:00:00 | AB9: =SUM(Y9:Z9) -> 0 | AC9: 0 | AD9: =V9=AC9 -> TRUE
M10: O | P10: =MROUND(L10,"0:15") -> 0 | Q10: =VALUE(MID(TEXT(L10,"hh:mm:ss"),4,2)+Q9)-IF(ABS((MID(TEXT(L10,"hh:mm:ss"),4,2)+Q9)-FLOOR((MID(TEXT(L10,"hh:mm:ss"),4,2)+Q9),15))>ABS((MID(TEXT(L10,"hh:mm:ss"),4,2)+Q9)-CEILING((MID(TEXT(L10,"hh:mm:ss"),4,2)+Q9),15)),CEILING((MID(TEXT(L10,"hh:mm:ss"),4,2)+Q9),15),FLOOR((MID(TEXT(L10,"hh:mm:ss"),4,2)+Q9),15)) -> 1 | T10: =T9-L10 -> 1.3333333 | V10: 0.45833333 | Y10: =IF(M10="O",P10 - AA10,"0:00:00") -> 0 | Z10: =IF(M10="C",P10,"0:00:00") -> 0:00:00 | AA10: =IF(P10="M",Q10-P10,"0:00:00") -> 0:00:00 | AB10: =SUM(Y10:Z10) -> 0 | AC10: 0.45833333 | AD10: =V10=AC10 -> TRUE
A11: 46143 | J11: 0 | K11: =IF((D11-C11)<=$F$2,0,(D11-C11)-$F$2) -> 0 | L11: =(I11-B11)-K11-(H11-G11)-J11 -> 0 | M11: O | P11: =MROUND(L11,"0:15") -> 0 | Q11: =VALUE(MID(TEXT(L11,"hh:mm:ss"),4,2)+Q10)-IF(ABS((MID(TEXT(L11,"hh:mm:ss"),4,2)+Q10)-FLOOR((MID(TEXT(L11,"hh:mm:ss"),4,2)+Q10),15))>ABS((MID(TEXT(L11,"hh:mm:ss"),4,2)+Q10)-CEILING((MID(TEXT(L11,"hh:mm:ss"),4,2)+Q10),15)),CEILING((MID(TEXT(L11,"hh:mm:ss"),4,2)+Q10),15),FLOOR((MID(TEXT(L11,"hh:mm:ss"),4,2)+Q10),15)) -> 1 | T11: =T10-L11 -> 1.3333333 | V11: 0.29166667 | W11: 45261 | Y11: =IF(M11="O",P11 - AA11,"0:00:00") -> 0 | Z11: =IF(M11="C",P11,"0:00:00") -> 0:00:00 | AA11: =IF(P11="M",Q11-P11,"0:00:00") -> 0:00:00 | AB11: =SUM(Y11:Z11) -> 0 | AC11: 0.29166667 | AD11: =V11=AC11 -> TRUE
A12: Semana 1 | L12: =SUM(L7:L11) -> 0 | P12: =SUM(P7:P11) -> 0 | W12: Semana 1
Q13: =Q11 -> 1
A14: 46146 | J14: 0 | K14: =IF((D14-C14)<=$F$2,0,(D14-C14)-$F$2) -> 0 | L14: =(I14-B14)-K14-(H14-G14)-J14 -> 0 | M14: O | P14: =MROUND(L14,"0:15") -> 0 | Q14: =VALUE(MID(TEXT(L14,"hh:mm:ss"),4,2)+Q13)-IF(ABS((MID(TEXT(L14,"hh:mm:ss"),4,2)+Q13)-FLOOR((MID(TEXT(L14,"hh:mm:ss"),4,2)+Q13),15))>ABS((MID(TEXT(L14,"hh:mm:ss"),4,2)+Q13)-CEILING((MID(TEXT(L14,"hh:mm:ss"),4,2)+Q13),15)),CEILING((MID(TEXT(L14,"hh:mm:ss"),4,2)+Q13),15),FLOOR((MID(TEXT(L14,"hh:mm:ss"),4,2)+Q13),15)) -> 1 | T14: =T11-L14 -> 1.3333333 | V14: 0.30208333 | W14: 45264 | Y14: =IF(M14="O",P14 - AA14,"0:00:00") -> 0 | Z14: =IF(M14="C",P14,"0:00:00") -> 0:00:00 | AA14: =IF(P14="M",Q14-P14,"0:00:00") -> 0:00:00 | AB14: =SUM(Y14:Z14) -> 0 | AC14: 0.30208333 | AD14: =V14=AC14 -> TRUE
A15: 46147 | J15: 0 | K15: =IF((D15-C15)<=$F$2,0,(D15-C15)-$F$2) -> 0 | L15: =(I15-B15)-K15-(H15-G15)-J15 -> 0 | M15: C | P15: =MROUND(L15,"0:15") -> 0 | Q15: =VALUE(MID(TEXT(L15,"hh:mm:ss"),4,2)+Q14)-IF(ABS((MID(TEXT(L15,"hh:mm:ss"),4,2)+Q14)-FLOOR((MID(TEXT(L15,"hh:mm:ss"),4,2)+Q14),15))>ABS((MID(TEXT(L15,"hh:mm:ss"),4,2)+Q14)-CEILING((MID(TEXT(L15,"hh:mm:ss"),4,2)+Q14),15)),CEILING((MID(TEXT(L15,"hh:mm:ss"),4,2)+Q14),15),FLOOR((MID(TEXT(L15,"hh:mm:ss"),4,2)+Q14),15)) -> 1 | T15: =T14-L15 -> 1.3333333 | V15: 0.25 | W15: 45265 | Y15: =IF(M15="O",P15 - AA15,"0:00:00") -> 0:00:00 | Z15: =IF(M15="C",P15,"0:00:00") -> 0 | AA15: =IF(P15="M",Q15-P15,"0:00:00") -> 0:00:00 | AB15: =SUM(Y15:Z15) -> 0 | AC15: 0.25 | AD15: =V15=AC15 -> TRUE
A16: 46148 | J16: 0 | K16: =IF((D16-C16)<=$F$2,0,(D16-C16)-$F$2) -> 0 | L16: =(I16-B16)-K16-(H16-G16)-J16 -> 0 | M16: O | P16: =MROUND(L16,"0:15") -> 0 | Q16: =VALUE(MID(TEXT(L16,"hh:mm:ss"),4,2)+Q15)-IF(ABS((MID(TEXT(L16,"hh:mm:ss"),4,2)+Q15)-FLOOR((MID(TEXT(L16,"hh:mm:ss"),4,2)+Q15),15))>ABS((MID(TEXT(L16,"hh:mm:ss"),4,2)+Q15)-CEILING((MID(TEXT(L16,"hh:mm:ss"),4,2)+Q15),15)),CEILING((MID(TEXT(L16,"hh:mm:ss"),4,2)+Q15),15),FLOOR((MID(TEXT(L16,"hh:mm:ss"),4,2)+Q15),15)) -> 1 | T16: =T15-P16 -> 1.3333333 | V16: 0.23958333 | W16: 45266 | Y16: =IF(M16="O",P16 - AA16,"0:00:00") -> 0 | Z16: =IF(M16="C",P16,"0:00:00") -> 0:00:00 | AA16: =IF(P16="M",Q16-P16,"0:00:00") -> 0:00:00 | AB16: =SUM(Y16:Z16) -> 0 | AC16: 0.23958333 | AD16: =V16=AC16 -> TRUE
A17: 46149 | J17: 0 | K17: =IF((D17-C17)<=$F$2,0,(D17-C17)-$F$2) -> 0 | L17: =(I17-B17)-K17-(H17-G17)-J17 -> 0 | M17: O | P17: =MROUND(L17,"0:15") -> 0 | Q17: =VALUE(MID(TEXT(L17,"hh:mm:ss"),4,2)+Q16)-IF(ABS((MID(TEXT(L17,"hh:mm:ss"),4,2)+Q16)-FLOOR((MID(TEXT(L17,"hh:mm:ss"),4,2)+Q16),15))>ABS((MID(TEXT(L17,"hh:mm:ss"),4,2)+Q16)-CEILING((MID(TEXT(L17,"hh:mm:ss"),4,2)+Q16),15)),CEILING((MID(TEXT(L17,"hh:mm:ss"),4,2)+Q16),15),FLOOR((MID(TEXT(L17,"hh:mm:ss"),4,2)+Q16),15)) -> 1 | T17: =T16-P17 -> 1.3333333 | V17: 0 | W17: 45267 | Y17: =IF(M17="O",P17 - AA17,"0:00:00") -> 0 | Z17: =IF(M17="C",P17,"0:00:00") -> 0:00:00 | AA17: =IF(P17="M",Q17-P17,"0:00:00") -> 0:00:00 | AB17: =SUM(Y17:Z17) -> 0 | AC17: 0 | AD17: =V17=AC17 -> TRUE
A18: 46150 | J18: 0 | K18: =IF((D18-C18)<=$F$2,0,(D18-C18)-$F$2) -> 0 | L18: =(I18-B18)-K18-(H18-G18)-J18 -> 0 | M18: C | P18: =MROUND(L18,"0:15") -> 0 | Q18: =VALUE(MID(TEXT(L18,"hh:mm:ss"),4,2)+Q17)-IF(ABS((MID(TEXT(L18,"hh:mm:ss"),4,2)+Q17)-FLOOR((MID(TEXT(L18,"hh:mm:ss"),4,2)+Q17),15))>ABS((MID(TEXT(L18,"hh:mm:ss"),4,2)+Q17)-CEILING((MID(TEXT(L18,"hh:mm:ss"),4,2)+Q17),15)),CEILING((MID(TEXT(L18,"hh:mm:ss"),4,2)+Q17),15),FLOOR((MID(TEXT(L18,"hh:mm:ss"),4,2)+Q17),15)) -> 1 | T18: =T17-L18 -> 1.3333333 | V18: 0 | W18: 45268 | Y18: =IF(M18="O",P18 - AA18,"0:00:00") -> 0:00:00 | Z18: =IF(M18="C",P18,"0:00:00") -> 0 | AA18: =IF(P18="M",Q18-P18,"0:00:00") -> 0:00:00 | AB18: =SUM(Y18:Z18) -> 0 | AC18: 0 | AD18: =V18=AC18 -> TRUE
A19: Semana 2 | L19: =SUM(L14:L18) -> 0 | P19: =SUM(P14:P18) -> 0 | W19: Semana 2
Q20: =Q18 -> 1
A21: 46184 | J21: 0 | K21: =IF((D21-C21)<=$F$2,0,(D21-C21)-$F$2) -> 0 | L21: =(I21-B21)-K21-(H21-G21)-J21 -> 0 | M21: O | P21: =MROUND(L21,"0:15") -> 0 | Q21: =VALUE(MID(TEXT(L21,"hh:mm:ss"),4,2)+Q20)-IF(ABS((MID(TEXT(L21,"hh:mm:ss"),4,2)+Q20)-FLOOR((MID(TEXT(L21,"hh:mm:ss"),4,2)+Q20),15))>ABS((MID(TEXT(L21,"hh:mm:ss"),4,2)+Q20)-CEILING((MID(TEXT(L21,"hh:mm:ss"),4,2)+Q20),15)),CEILING((MID(TEXT(L21,"hh:mm:ss"),4,2)+Q20),15),FLOOR((MID(TEXT(L21,"hh:mm:ss"),4,2)+Q20),15)) -> 1 | T21: =T18-L21 -> 1.3333333 | V21: 0.36458333 | W21: 45271 | Y21: =IF(M21="O",P21 - AA21,"0:00:00") -> 0 | Z21: =IF(M21="C",P21,"0:00:00") -> 0:00:00 | AA21: =IF(P21="M",Q21-P21,"0:00:00") -> 0:00:00 | AB21: =SUM(Y21:Z21) -> 0 | AC21: 0.36458333 | AD21: =V21=AC21 -> TRUE
A22: 46185 | J22: 0 | K22: =IF((D22-C22)<=$F$2,0,(D22-C22)-$F$2) -> 0 | L22: =(I22-B22)-K22-(H22-G22)-J22 -> 0 | M22: C | P22: =MROUND(L22,"0:15") -> 0 | Q22: =VALUE(MID(TEXT(L22,"hh:mm:ss"),4,2)+Q21)-IF(ABS((MID(TEXT(L22,"hh:mm:ss"),4,2)+Q21)-FLOOR((MID(TEXT(L22,"hh:mm:ss"),4,2)+Q21),15))>ABS((MID(TEXT(L22,"hh:mm:ss"),4,2)+Q21)-CEILING((MID(TEXT(L22,"hh:mm:ss"),4,2)+Q21),15)),CEILING((MID(TEXT(L22,"hh:mm:ss"),4,2)+Q21),15),FLOOR((MID(TEXT(L22,"hh:mm:ss"),4,2)+Q21),15)) -> 1 | T22: =T21-L22 -> 1.3333333 | V22: 0.36458333 | W22: 45272 | Y22: =IF(M22="O",P22 - AA22,"0:00:00") -> 0:00:00 | Z22: =IF(M22="C",P22,"0:00:00") -> 0 | AA22: =IF(P22="M",Q22-P22,"0:00:00") -> 0:00:00 | AB22: =SUM(Y22:Z22) -> 0 | AC22: 0.36458333 | AD22: =V22=AC22 -> TRUE
A23: 46186 | J23: 0 | K23: =IF((D23-C23)<=$F$2,0,(D23-C23)-$F$2) -> 0 | L23: =(I23-B23)-K23-(H23-G23)-J23 -> 0 | M23: O | P23: =MROUND(L23,"0:15") -> 0 | Q23: =VALUE(MID(TEXT(L23,"hh:mm:ss"),4,2)+Q22)-IF(ABS((MID(TEXT(L23,"hh:mm:ss"),4,2)+Q22)-FLOOR((MID(TEXT(L23,"hh:mm:ss"),4,2)+Q22),15))>ABS((MID(TEXT(L23,"hh:mm:ss"),4,2)+Q22)-CEILING((MID(TEXT(L23,"hh:mm:ss"),4,2)+Q22),15)),CEILING((MID(TEXT(L23,"hh:mm:ss"),4,2)+Q22),15),FLOOR((MID(TEXT(L23,"hh:mm:ss"),4,2)+Q22),15)) -> 1 | T23: =T22-L23 -> 1.3333333 | V23: 0.45833333 | W23: 45273 | Y23: =IF(M23="O",P23 - AA23,"0:00:00") -> 0 | Z23: =IF(M23="C",P23,"0:00:00") -> 0:00:00 | AA23: =IF(P23="M",Q23-P23,"0:00:00") -> 0:00:00 | AB23: =SUM(Y23:Z23) -> 0 | AC23: 0.45833333 | AD23: =V23=AC23 -> TRUE
A24: 46187 | J24: 0 | K24: =IF((D24-C24)<=$F$2,0,(D24-C24)-$F$2) -> 0 | L24: =(I24-B24)-K24-(H24-G24)-J24 -> 0 | M24: C | P24: =MROUND(L24,"0:15") -> 0 | Q24: =VALUE(MID(TEXT(L24,"hh:mm:ss"),4,2)+Q23)-IF(ABS((MID(TEXT(L24,"hh:mm:ss"),4,2)+Q23)-FLOOR((MID(TEXT(L24,"hh:mm:ss"),4,2)+Q23),15))>ABS((MID(TEXT(L24,"hh:mm:ss"),4,2)+Q23)-CEILING((MID(TEXT(L24,"hh:mm:ss"),4,2)+Q23),15)),CEILING((MID(TEXT(L24,"hh:mm:ss"),4,2)+Q23),15),FLOOR((MID(TEXT(L24,"hh:mm:ss"),4,2)+Q23),15)) -> 1 | T24: =T23-L24 -> 1.3333333 | V24: 0.32291667 | W24: 45274 | Y24: =IF(M24="O",P24 - AA24,"0:00:00") -> 0:00:00 | Z24: =IF(M24="C",P24,"0:00:00") -> 0 | AA24: =IF(P24="M",Q24-P24,"0:00:00") -> 0:00:00 | AB24: =SUM(Y24:Z24) -> 0 | AC24: 0.32291667 | AD24: =V24=AC24 -> TRUE
A25: 46188 | J25: 0 | K25: =IF((D25-C25)<=$F$2,0,(D25-C25)-$F$2) -> 0 | L25: =(I25-B25)-K25-(H25-G25)-J25 -> 0 | M25: C | P25: =MROUND(L25,"0:15") -> 0 | Q25: =VALUE(MID(TEXT(L25,"hh:mm:ss"),4,2)+Q24)-IF(ABS((MID(TEXT(L25,"hh:mm:ss"),4,2)+Q24)-FLOOR((MID(TEXT(L25,"hh:mm:ss"),4,2)+Q24),15))>ABS((MID(TEXT(L25,"hh:mm:ss"),4,2)+Q24)-CEILING((MID(TEXT(L25,"hh:mm:ss"),4,2)+Q24),15)),CEILING((MID(TEXT(L25,"hh:mm:ss"),4,2)+Q24),15),FLOOR((MID(TEXT(L25,"hh:mm:ss"),4,2)+Q24),15)) -> 1 | T25: =T24-L25 -> 1.3333333 | V25: 0.36458333 | W25: 45275 | Y25: =IF(M25="O",P25 - AA25,"0:00:00") -> 0:00:00 | Z25: =IF(M25="C",P25,"0:00:00") -> 0 | AA25: =IF(P25="M",Q25-P25,"0:00:00") -> 0:00:00 | AB25: =SUM(Y25:Z25) -> 0 | AC25: 0.36458333 | AD25: =V25=AC25 -> TRUE
A26: Semana 3 | L26: =SUM(L21:L25) -> 0 | P26: =SUM(P21:P25) -> 0 | W26: Semana 3
Q27: =Q25 -> 1
A28: 46160 | J28: 0 | K28: =IF((D28-C28)<=$F$2,0,(D28-C28)-$F$2) -> 0 | L28: =(I28-B28)-K28-(H28-G28)-J28 -> 0 | M28: O | P28: =MROUND(L28,"0:15") -> 0 | Q28: =VALUE(MID(TEXT(L28,"hh:mm:ss"),4,2)+Q27)-IF(ABS((MID(TEXT(L28,"hh:mm:ss"),4,2)+Q27)-FLOOR((MID(TEXT(L28,"hh:mm:ss"),4,2)+Q27),15))>ABS((MID(TEXT(L28,"hh:mm:ss"),4,2)+Q27)-CEILING((MID(TEXT(L28,"hh:mm:ss"),4,2)+Q27),15)),CEILING((MID(TEXT(L28,"hh:mm:ss"),4,2)+Q27),15),FLOOR((MID(TEXT(L28,"hh:mm:ss"),4,2)+Q27),15)) -> 1 | T28: =T25-L28 -> 1.3333333 | V28: 0.30208333 | W28: 45278 | Y28: =IF(M28="O",P28 - AA28,"0:00:00") -> 0 | Z28: =IF(M28="C",P28,"0:00:00") -> 0:00:00 | AA28: =IF(P28="M",Q28-P28,"0:00:00") -> 0:00:00 | AB28: =SUM(Y28:Z28) -> 0 | AC28: 0.30208333 | AD28: =V28=AC28 -> TRUE
A29: 46161 | J29: 0 | K29: =IF((D29-C29)<=$F$2,0,(D29-C29)-$F$2) -> 0 | L29: =(I29-B29)-K29-(H29-G29)-J29 -> 0 | M29: C | P29: =MROUND(L29,"0:15") -> 0 | Q29: =VALUE(MID(TEXT(L29,"hh:mm:ss"),4,2)+Q28)-IF(ABS((MID(TEXT(L29,"hh:mm:ss"),4,2)+Q28)-FLOOR((MID(TEXT(L29,"hh:mm:ss"),4,2)+Q28),15))>ABS((MID(TEXT(L29,"hh:mm:ss"),4,2)+Q28)-CEILING((MID(TEXT(L29,"hh:mm:ss"),4,2)+Q28),15)),CEILING((MID(TEXT(L29,"hh:mm:ss"),4,2)+Q28),15),FLOOR((MID(TEXT(L29,"hh:mm:ss"),4,2)+Q28),15)) -> 1 | T29: =T28-L29 -> 1.3333333 | V29: 0 | W29: 45279 | Y29: =IF(M29="O",P29 - AA29,"0:00:00") -> 0:00:00 | Z29: =IF(M29="C",P29,"0:00:00") -> 0 | AA29: =IF(P29="M",Q29-P29,"0:00:00") -> 0:00:00 | AB29: =SUM(Y29:Z29) -> 0 | AC29: 0.21875 | AD29: =V29=AC29 -> FALSE
A30: 46162 | J30: 0 | K30: =IF((D30-C30)<=$F$2,0,(D30-C30)-$F$2) -> 0 | L30: =(I30-B30)-K30-(H30-G30)-J30 -> 0 | M30: O | P30: =MROUND(L30,"0:15") -> 0 | Q30: =VALUE(MID(TEXT(L30,"hh:mm:ss"),4,2)+Q29)-IF(ABS((MID(TEXT(L30,"hh:mm:ss"),4,2)+Q29)-FLOOR((MID(TEXT(L30,"hh:mm:ss"),4,2)+Q29),15))>ABS((MID(TEXT(L30,"hh:mm:ss"),4,2)+Q29)-CEILING((MID(TEXT(L30,"hh:mm:ss"),4,2)+Q29),15)),CEILING((MID(TEXT(L30,"hh:mm:ss"),4,2)+Q29),15),FLOOR((MID(TEXT(L30,"hh:mm:ss"),4,2)+Q29),15)) -> 1 | T30: =T29-L30 -> 1.3333333 | V30: 0.35416667 | W30: 45280 | Y30: =IF(M30="O",P30 - AA30,"0:00:00") -> 0 | Z30: =IF(M30="C",P30,"0:00:00") -> 0:00:00 | AA30: =IF(P30="M",Q30-P30,"0:00:00") -> 0:00:00 | AB30: =SUM(Y30:Z30) -> 0 | AC30: 0.30208333 | AD30: =V30=AC30 -> FALSE
A31: 46163 | J31: 0 | K31: =IF((D31-C31)<=$F$2,0,(D31-C31)-$F$2) -> 0 | L31: =(I31-B31)-K31-(H31-G31)-J31 -> 0 | M31: O | P31: =MROUND(L31,"0:15") -> 0 | Q31: =VALUE(MID(TEXT(L31,"hh:mm:ss"),4,2)+Q30)-IF(ABS((MID(TEXT(L31,"hh:mm:ss"),4,2)+Q30)-FLOOR((MID(TEXT(L31,"hh:mm:ss"),4,2)+Q30),15))>ABS((MID(TEXT(L31,"hh:mm:ss"),4,2)+Q30)-CEILING((MID(TEXT(L31,"hh:mm:ss"),4,2)+Q30),15)),CEILING((MID(TEXT(L31,"hh:mm:ss"),4,2)+Q30),15),FLOOR((MID(TEXT(L31,"hh:mm:ss"),4,2)+Q30),15)) -> 1 | T31: =T30-L31 -> 1.3333333 | V31: 0.41666667 | W31: 45281 | Y31: =IF(M31="O",P31 - AA31,"0:00:00") -> 0 | Z31: =IF(M31="C",P31,"0:00:00") -> 0:00:00 | AA31: =IF(P31="M",Q31-P31,"0:00:00") -> 0:00:00 | AB31: =SUM(Y31:Z31) -> 0 | AC31: 0.30208333 | AD31: =V31=AC31 -> FALSE
A32: 46164 | J32: 0 | K32: =IF((D32-C32)<=$F$2,0,(D32-C32)-$F$2) -> 0 | L32: =(I32-B32)-K32-(H32-G32)-J32 -> 0 | M32: C | P32: =MROUND(L32,"0:15") -> 0 | Q32: =VALUE(MID(TEXT(L32,"hh:mm:ss"),4,2)+Q31)-IF(ABS((MID(TEXT(L32,"hh:mm:ss"),4,2)+Q31)-FLOOR((MID(TEXT(L32,"hh:mm:ss"),4,2)+Q31),15))>ABS((MID(TEXT(L32,"hh:mm:ss"),4,2)+Q31)-CEILING((MID(TEXT(L32,"hh:mm:ss"),4,2)+Q31),15)),CEILING((MID(TEXT(L32,"hh:mm:ss"),4,2)+Q31),15),FLOOR((MID(TEXT(L32,"hh:mm:ss"),4,2)+Q31),15)) -> 1 | T32: =T31-L32 -> 1.3333333 | V32: 0.35416667 | W32: 45282 | Y32: =IF(M32="O",P32 - AA32,"0:00:00") -> 0:00:00 | Z32: =IF(M32="C",P32,"0:00:00") -> 0 | AA32: =IF(P32="M",Q32-P32,"0:00:00") -> 0:00:00 | AB32: =SUM(Y32:Z32) -> 0 | AC32: 0.30208333 | AD32: =V32=AC32 -> FALSE
A33: Semana 4 | L33: =SUM(L28:L32) -> 0 | P33: =SUM(P28:P32) -> 0 | W33: Semana 4
Q34: =Q32 -> 1
A35: 46167 | J35: 0 | K35: 0 | L35: 0 | M35: O | P35: =MROUND(L35,"0:15") -> 0 | Q35: =VALUE(MID(TEXT(L35,"hh:mm:ss"),4,2)+Q34)-IF(ABS((MID(TEXT(L35,"hh:mm:ss"),4,2)+Q34)-FLOOR((MID(TEXT(L35,"hh:mm:ss"),4,2)+Q34),15))>ABS((MID(TEXT(L35,"hh:mm:ss"),4,2)+Q34)-CEILING((MID(TEXT(L35,"hh:mm:ss"),4,2)+Q34),15)),CEILING((MID(TEXT(L35,"hh:mm:ss"),4,2)+Q34),15),FLOOR((MID(TEXT(L35,"hh:mm:ss"),4,2)+Q34),15)) -> 1 | T35: =T32-L35 -> 1.3333333 | V35: 0.33333333 | W35: 45285 | Y35: =IF(M35="O",P35 - AA35,"0:00:00") -> 0 | Z35: =IF(M35="C",P35,"0:00:00") -> 0:00:00 | AA35: =IF(P35="M",Q35-P35,"0:00:00") -> 0:00:00 | AB35: =SUM(Y35:Z35) -> 0 | AC35: 0.33333333 | AD35: =V35=AC35 -> TRUE
A36: 46168 | B36: 0.30902778 | C36: 0.52986111 | D36: 0.54305556 | E36: 0.62638889 | F36: 0.64722222 | I36: 0.74930556 | J36: 0.020833333 | K36: 0 | L36: =(I36-B36)-K36-(H36-G36)-J36 -> 0.41944444 | M36: C | P36: =TIME(MID(TEXT(L36,"hh:mm:ss"),1,2), IF(ABS((MID(TEXT(L36,"hh:mm:ss"),4,2)+Q35)-FLOOR((MID(TEXT(L36,"hh:mm:ss"),4,2)+Q35),15))>=ABS((MID(TEXT(L36,"hh:mm:ss"),4,2)+Q35)-CEILING((MID(TEXT(L36,"hh:mm:ss"),4,2)+Q35),15)),CEILING((MID(TEXT(L36,"hh:mm:ss"),4,2)+Q35),15),FLOOR((MID(TEXT(L36,"hh:mm:ss"),4,2)+Q35),15)), MID(TEXT(L36,"hh:mm:ss"),7,2)) -> 0.41666667 | Q36: =VALUE(MID(TEXT(L36,"hh:mm:ss"),4,2)+Q35)-IF(ABS((MID(TEXT(L36,"hh:mm:ss"),4,2)+Q35)-FLOOR((MID(TEXT(L36,"hh:mm:ss"),4,2)+Q35),15))>ABS((MID(TEXT(L36,"hh:mm:ss"),4,2)+Q35)-CEILING((MID(TEXT(L36,"hh:mm:ss"),4,2)+Q35),15)),CEILING((MID(TEXT(L36,"hh:mm:ss"),4,2)+Q35),15),FLOOR((MID(TEXT(L36,"hh:mm:ss"),4,2)+Q35),15)) -> 5 | T36: =T35-L36 -> 0.91388889 | V36: 0.45833333 | W36: 45286 | Y36: =IF(M36="O",P36 - AA36,"0:00:00") -> 0:00:00 | Z36: =IF(M36="C",P36,"0:00:00") -> 0.41666667 | AA36: =IF(P36="M",Q36-P36,"0:00:00") -> 0:00:00 | AB36: =SUM(Y36:Z36) -> 0.41666667 | AC36: 0.45833333 | AD36: =V36=AC36 -> TRUE
A37: 46169 | B37: 0.30347222 | C37: 0.49236111 | D37: 0.50625 | I37: 0.62638889 | J37: 0 | K37: 0 | L37: =(I37-B37)-K37-(H37-G37)-J37 -> 0.32291667 | M37: O | P37: =TIME(MID(TEXT(L37,"hh:mm:ss"),1,2), IF(ABS((MID(TEXT(L37,"hh:mm:ss"),4,2)+Q36)-FLOOR((MID(TEXT(L37,"hh:mm:ss"),4,2)+Q36),15))>=ABS((MID(TEXT(L37,"hh:mm:ss"),4,2)+Q36)-CEILING((MID(TEXT(L37,"hh:mm:ss"),4,2)+Q36),15)),CEILING((MID(TEXT(L37,"hh:mm:ss"),4,2)+Q36),15),FLOOR((MID(TEXT(L37,"hh:mm:ss"),4,2)+Q36),15)), MID(TEXT(L37,"hh:mm:ss"),7,2)) -> 0.32291667 | Q37: =VALUE(MID(TEXT(L37,"hh:mm:ss"),4,2)+Q36)-IF(ABS((MID(TEXT(L37,"hh:mm:ss"),4,2)+Q36)-FLOOR((MID(TEXT(L37,"hh:mm:ss"),4,2)+Q36),15))>ABS((MID(TEXT(L37,"hh:mm:ss"),4,2)+Q36)-CEILING((MID(TEXT(L37,"hh:mm:ss"),4,2)+Q36),15)),CEILING((MID(TEXT(L37,"hh:mm:ss"),4,2)+Q36),15),FLOOR((MID(TEXT(L37,"hh:mm:ss"),4,2)+Q36),15)) -> 5 | T37: =T36-L37 -> 0.59097222 | V37: 0.33333333 | W37: 45287 | Y37: =IF(M37="O",P37 - AA37,"0:00:00") -> 0.32291667 | Z37: =IF(M37="C",P37,"0:00:00") -> 0:00:00 | AA37: =IF(P37="M",Q37-P37,"0:00:00") -> 0:00:00 | AB37: =SUM(Y37:Z37) -> 0.32291667 | AC37: 0.33333333 | AD37: =V37=AC37 -> TRUE
A38: 46170 | B38: 0.33333333 | I38: 0.66666667 | J38: 0 | K38: 0 | L38: =(I38-B38)-K38-(H38-G38)-J38 -> 0.33333333 | M38: C | P38: =TIME(MID(TEXT(L38,"hh:mm:ss"),1,2), IF(ABS((MID(TEXT(L38,"hh:mm:ss"),4,2)+Q37)-FLOOR((MID(TEXT(L38,"hh:mm:ss"),4,2)+Q37),15))>=ABS((MID(TEXT(L38,"hh:mm:ss"),4,2)+Q37)-CEILING((MID(TEXT(L38,"hh:mm:ss"),4,2)+Q37),15)),CEILING((MID(TEXT(L38,"hh:mm:ss"),4,2)+Q37),15),FLOOR((MID(TEXT(L38,"hh:mm:ss"),4,2)+Q37),15)), MID(TEXT(L38,"hh:mm:ss"),7,2)) -> 0.33333333 | Q38: =VALUE(MID(TEXT(L38,"hh:mm:ss"),4,2)+Q37)-IF(ABS((MID(TEXT(L38,"hh:mm:ss"),4,2)+Q37)-FLOOR((MID(TEXT(L38,"hh:mm:ss"),4,2)+Q37),15))>ABS((MID(TEXT(L38,"hh:mm:ss"),4,2)+Q37)-CEILING((MID(TEXT(L38,"hh:mm:ss"),4,2)+Q37),15)),CEILING((MID(TEXT(L38,"hh:mm:ss"),4,2)+Q37),15),FLOOR((MID(TEXT(L38,"hh:mm:ss"),4,2)+Q37),15)) -> 5 | T38: =T37-L38 -> 0.25763889 | V38: 0.45833333 | W38: 45288 | Y38: =IF(M38="O",P38 - AA38,"0:00:00") -> 0:00:00 | Z38: =IF(M38="C",P38,"0:00:00") -> 0.33333333 | AA38: =IF(P38="M",Q38-P38,"0:00:00") -> 0:00:00 | AB38: =SUM(Y38:Z38) -> 0.33333333 | AC38: 0.45833333 | AD38: =V38=AC38 -> TRUE
A39: 46171 | B39: 0.33263889 | C39: 0.50625 | D39: 0.52013889 | I39: 0.65277778 | J39: 0 | K39: 6.2450045e-17 | L39: =(I39-B39)-K39-(H39-G39)-J39 -> 0.32013889 | M39: C | P39: =TIME(MID(TEXT(L39,"hh:mm:ss"),1,2), IF(ABS((MID(TEXT(L39,"hh:mm:ss"),4,2)+Q38)-FLOOR((MID(TEXT(L39,"hh:mm:ss"),4,2)+Q38),15))>=ABS((MID(TEXT(L39,"hh:mm:ss"),4,2)+Q38)-CEILING((MID(TEXT(L39,"hh:mm:ss"),4,2)+Q38),15)),CEILING((MID(TEXT(L39,"hh:mm:ss"),4,2)+Q38),15),FLOOR((MID(TEXT(L39,"hh:mm:ss"),4,2)+Q38),15)), MID(TEXT(L39,"hh:mm:ss"),7,2)) -> 0.32291667 | Q39: =VALUE(MID(TEXT(L39,"hh:mm:ss"),4,2)+Q38)-IF(ABS((MID(TEXT(L39,"hh:mm:ss"),4,2)+Q38)-FLOOR((MID(TEXT(L39,"hh:mm:ss"),4,2)+Q38),15))>ABS((MID(TEXT(L39,"hh:mm:ss"),4,2)+Q38)-CEILING((MID(TEXT(L39,"hh:mm:ss"),4,2)+Q38),15)),CEILING((MID(TEXT(L39,"hh:mm:ss"),4,2)+Q38),15),FLOOR((MID(TEXT(L39,"hh:mm:ss"),4,2)+Q38),15)) -> 1 | T39: =T38-L39 -> -0.0625 | W39: 45289 | Y39: =IF(M39="O",P39 - AA39,"0:00:00") -> 0:00:00 | Z39: =IF(M39="C",P39,"0:00:00") -> 0.32291667 | AA39: =IF(P39="M",Q39-P39,"0:00:00") -> 0:00:00 | AB39: =SUM(Y39:Z39) -> 0.32291667
A40: Semana 5 | L40: =SUM(L35:L39) -> 1.3958333 | P40: =SUM(P35:P39) -> 1.3958333 | W40: Semana 5
...

Sheet Junio
A1: Empresa: | B1: IZERTIS | E1: Tiempo min comida | F1: 0.020833333 | I1: Dias Mes: | J1: 10 | K1: Dias Mes: | L1: 12
A2: Nombre: | E2: Tiempo desayuno | F2: 0.013888889 | I2: Horas / Día: | J2: 0.33333333 | K2: Horas / Día: | L2: 0.29166667
A3: Mes: | B3: 46174 | E3: % R.Domic. | F3: 50 | I3: Días R.Dom: | J3: 8
N4: Teletrabajo tardes MIXTO
A5: Día | B5: ENTRADA | C5: Salida Desay | D5: Entrada Desay | E5: Salida Comida | F5: Entrada Comida | G5: Hora Salida | H5: Hora Entrada | I5: SALIDA | J5: Total Comida | K5: Total Desayuno | L5: Total Día | M5: Ubic | N5: Entrada Comida | O5: SALIDA | T5: =C46 -> 6.8333333 | V5: JIRA | W5: Día | Y5: CONTROL TELETRABAJO | AC5: IZERTIA | AD5: IZERTIA/JIRA
Q6: 1 | Y6: OFICINA | Z6: CASA | AA6: MIXTA T. | AB6: Total
A7: 46174 | B7: 0.30138889 | C7: 0.48402778 | D7: 0.49861111 | I7: 0.62569444 | J7: 0 | K7: =IF((D7-C7)<=$F$2,0,(D7-C7)-$F$2) -> 0.00069444444 | L7: =(I7-B7)-K7-(H7-G7)-J7 -> 0.32361111 | M7: O | P7: =MROUND(L7,"0:15") -> 0.32291667 | Q7: =VALUE(MID(TEXT(L7,"hh:mm:ss"),4,2)+Q6)-IF(ABS((MID(TEXT(L7,"hh:mm:ss"),4,2)+Q6)-FLOOR((MID(TEXT(L7,"hh:mm:ss"),4,2)+Q6),15))>ABS((MID(TEXT(L7,"hh:mm:ss"),4,2)+Q6)-CEILING((MID(TEXT(L7,"hh:mm:ss"),4,2)+Q6),15)),CEILING((MID(TEXT(L7,"hh:mm:ss"),4,2)+Q6),15),FLOOR((MID(TEXT(L7,"hh:mm:ss"),4,2)+Q6),15)) -> 2 | T7: =T5-L7 -> 6.5097222 | V7: 0 | Y7: =IF(M7="O",P7 - AA7,"0:00:00") -> 0.32291667 | Z7: =IF(M7="C",P7,"0:00:00") -> 0:00:00 | AA7: =IF(P7="M",Q7-P7,"0:00:00") -> 0:00:00 | AB7: =SUM(Y7:Z7) -> 0.32291667 | AC7: 0
A8: 46175 | B8: 0.32916667 | C8: 0.5125 | D8: 0.52638889 | I8: 0.66875 | J8: 0 | K8: =IF((D8-C8)<=$F$2,0,(D8-C8)-$F$2) -> 0 | L8: =(I8-B8)-K8-(H8-G8)-J8 -> 0.33958333 | M8: C | P8: =MROUND(L8,"0:15") -> 0.34375 | Q8: =VALUE(MID(TEXT(L8,"hh:mm:ss"),4,2)+Q7)-IF(ABS((MID(TEXT(L8,"hh:mm:ss"),4,2)+Q7)-FLOOR((MID(TEXT(L8,"hh:mm:ss"),4,2)+Q7),15))>ABS((MID(TEXT(L8,"hh:mm:ss"),4,2)+Q7)-CEILING((MID(TEXT(L8,"hh:mm:ss"),4,2)+Q7),15)),CEILING((MID(TEXT(L8,"hh:mm:ss"),4,2)+Q7),15),FLOOR((MID(TEXT(L8,"hh:mm:ss"),4,2)+Q7),15)) -> -4 | T8: =T7-L8 -> 6.1701389 | V8: 0 | Y8: =IF(M8="O",P8 - AA8,"0:00:00") -> 0:00:00 | Z8: =IF(M8="C",P8,"0:00:00") -> 0.34375 | AA8: 0 | AB8: =SUM(Y8:Z8) -> 0.34375 | AC8: 0
A9: 46176 | B9: 0.30208333 | C9: 0.475 | D9: 0.48819444 | I9: 0.60555556 | J9: 0 | K9: =IF((D9-C9)<=$F$2,0,(D9-C9)-$F$2) -> 0 | L9: =(I9-B9)-K9-(H9-G9)-J9 -> 0.30347222 | M9: O | P9: =MROUND(L9,"0:15") -> 0.30208333 | Q9: =VALUE(MID(TEXT(L9,"hh:mm:ss"),4,2)+Q8)-IF(ABS((MID(TEXT(L9,"hh:mm:ss"),4,2)+Q8)-FLOOR((MID(TEXT(L9,"hh:mm:ss"),4,2)+Q8),15))>ABS((MID(TEXT(L9,"hh:mm:ss"),4,2)+Q8)-CEILING((MID(TEXT(L9,"hh:mm:ss"),4,2)+Q8),15)),CEILING((MID(TEXT(L9,"hh:mm:ss"),4,2)+Q8),15),FLOOR((MID(TEXT(L9,"hh:mm:ss"),4,2)+Q8),15)) -> -2 | T9: =T8-L9 -> 5.8666667 | V9: 0 | Y9: =IF(M9="O",P9 - AA9,"0:00:00") -> 0.30208333 | Z9: =IF(M9="C",P9,"0:00:00") -> 0:00:00 | AA9: =IF(P9="M",Q9-P9,"0:00:00") -> 0:00:00 | AB9: =SUM(Y9:Z9) -> 0.30208333 | AC9: 0 | AD9: =V9=AC9 -> TRUE
A10: 46177 | B10: 0.31666667 | C10: 0.51041667 | D10: 0.52361111 | E10: 0.64861111 | F10: 0.66944444 | I10: 0.71111111 | J10: =IF((F10-E10)<$F$1,$F$1,F10-E10) -> 0.020833333 | K10: =IF((D10-C10)<=$F$2,0,(D10-C10)-$F$2) -> 0 | L10: =(I10-B10)-K10-(H10-G10)-J10 -> 0.37361111 | M10: O | P10: =MROUND(L10,"0:15") -> 0.375 | Q10: =VALUE(MID(TEXT(L10,"hh:mm:ss"),4,2)+Q9)-IF(ABS((MID(TEXT(L10,"hh:mm:ss"),4,2)+Q9)-FLOOR((MID(TEXT(L10,"hh:mm:ss"),4,2)+Q9),15))>ABS((MID(TEXT(L10,"hh:mm:ss"),4,2)+Q9)-CEILING((MID(TEXT(L10,"hh:mm:ss"),4,2)+Q9),15)),CEILING((MID(TEXT(L10,"hh:mm:ss"),4,2)+Q9),15),FLOOR((MID(TEXT(L10,"hh:mm:ss"),4,2)+Q9),15)) -> -4 | T10: =T9-L10 -> 5.4930556 | V10: 0.45833333 | Y10: =IF(M10="O",P10 - AA10,"0:00:00") -> 0.375 | Z10: =IF(M10="C",P10,"0:00:00") -> 0:00:00 | AA10: =IF(P10="M",Q10-P10,"0:00:00") -> 0:00:00 | AB10: =SUM(Y10:Z10) -> 0.375 | AC10: 0.45833333 | AD10: =V10=AC10 -> TRUE
A11: 46178 | B11: 0.30138889 | I11: 0.59722222 | J11: 0 | K11: =IF((D11-C11)<=$F$2,0,(D11-C11)-$F$2) -> 0 | L11: =(I11-B11)-K11-(H11-G11)-J11 -> 0.29583333 | M11: O | P11: =MROUND(L11,"0:15") -> 0.29166667 | Q11: =VALUE(MID(TEXT(L11,"hh:mm:ss"),4,2)+Q10)-IF(ABS((MID(TEXT(L11,"hh:mm:ss"),4,2)+Q10)-FLOOR((MID(TEXT(L11,"hh:mm:ss"),4,2)+Q10),15))>ABS((MID(TEXT(L11,"hh:mm:ss"),4,2)+Q10)-CEILING((MID(TEXT(L11,"hh:mm:ss"),4,2)+Q10),15)),CEILING((MID(TEXT(L11,"hh:mm:ss"),4,2)+Q10),15),FLOOR((MID(TEXT(L11,"hh:mm:ss"),4,2)+Q10),15)) -> 2 | T11: =T10-L11 -> 5.1972222 | V11: 0.29166667 | W11: 45261 | Y11: =IF(M11="O",P11 - AA11,"0:00:00") -> 0.29166667 | Z11: =IF(M11="C",P11,"0:00:00") -> 0:00:00 | AA11: =IF(P11="M",Q11-P11,"0:00:00") -> 0:00:00 | AB11: =SUM(Y11:Z11) -> 0.29166667 | AC11: 0.29166667 | AD11: =V11=AC11 -> TRUE
A12: Semana 1 | L12: =SUM(L7:L11) -> 1.6361111 | P12: =SUM(P7:P11) -> 1.6354167 | W12: Semana 1
Q13: =Q11 -> 2
A14: 46181 | B14: 0.32847222 | C14: 0.51736111 | D14: 0.53125 | I14: 0.64652778 | J14: 0 | K14: =IF((D14-C14)<=$F$2,0,(D14-C14)-$F$2) -> 6.2450045e-17 | L14: =(I14-B14)-K14-(H14-G14)-J14 -> 0.31805556 | M14: O | P14: =MROUND(L14,"0:15") -> 0.32291667 | Q14: =VALUE(MID(TEXT(L14,"hh:mm:ss"),4,2)+Q13)-IF(ABS((MID(TEXT(L14,"hh:mm:ss"),4,2)+Q13)-FLOOR((MID(TEXT(L14,"hh:mm:ss"),4,2)+Q13),15))>ABS((MID(TEXT(L14,"hh:mm:ss"),4,2)+Q13)-CEILING((MID(TEXT(L14,"hh:mm:ss"),4,2)+Q13),15)),CEILING((MID(TEXT(L14,"hh:mm:ss"),4,2)+Q13),15),FLOOR((MID(TEXT(L14,"hh:mm:ss"),4,2)+Q13),15)) -> -5 | T14: =T11-L14 -> 4.8791667 | V14: 0.30208333 | W14: 45264 | Y14: =IF(M14="O",P14 - AA14,"0:00:00") -> 0.32291667 | Z14: =IF(M14="C",P14,"0:00:00") -> 0:00:00 | AA14: =IF(P14="M",Q14-P14,"0:00:00") -> 0:00:00 | AB14: =SUM(Y14:Z14) -> 0.32291667 | AC14: 0.30208333 | AD14: =V14=AC14 -> TRUE
A15: 46182 | B15: 0.32569444 | C15: 0.54791667 | D15: 0.56111111 | E15: 0.66180556 | F15: 0.67986111 | I15: 0.73263889 | J15: =IF((F15-E15)<$F$1,$F$1,F15-E15) -> 0.020833333 | K15: =IF((D15-C15)<=$F$2,0,(D15-C15)-$F$2) -> 0 | L15: =(I15-B15)-K15-(H15-G15)-J15 -> 0.38611111 | M15: O | P15: =MROUND(L15,"0:15") -> 0.38541667 | Q15: =VALUE(MID(TEXT(L15,"hh:mm:ss"),4,2)+Q14)-IF(ABS((MID(TEXT(L15,"hh:mm:ss"),4,2)+Q14)-FLOOR((MID(TEXT(L15,"hh:mm:ss"),4,2)+Q14),15))>ABS((MID(TEXT(L15,"hh:mm:ss"),4,2)+Q14)-CEILING((MID(TEXT(L15,"hh:mm:ss"),4,2)+Q14),15)),CEILING((MID(TEXT(L15,"hh:mm:ss"),4,2)+Q14),15),FLOOR((MID(TEXT(L15,"hh:mm:ss"),4,2)+Q14),15)) -> -4 | T15: =T14-L15 -> 4.4930556 | V15: 0.25 | W15: 45265 | Y15: =IF(M15="O",P15 - AA15,"0:00:00") -> 0.38541667 | Z15: =IF(M15="C",P15,"0:00:00") -> 0:00:00 | AA15: =IF(P15="M",Q15-P15,"0:00:00") -> 0:00:00 | AB15: =SUM(Y15:Z15) -> 0.38541667 | AC15: 0.25 | AD15: =V15=AC15 -> TRUE
A16: 46183 | B16: 0.30416667 | C16: 0.49236111 | D16: 0.51527778 | I16: 0.59444444 | J16: 0 | K16: =IF((D16-C16)<=$F$2,0,(D16-C16)-$F$2) -> 0.0090277778 | L16: =(I16-B16)-K16-(H16-G16)-J16 -> 0.28125 | M16: O | P16: =MROUND(L16,"0:15") -> 0.28125 | Q16: =VALUE(MID(TEXT(L16,"hh:mm:ss"),4,2)+Q15)-IF(ABS((MID(TEXT(L16,"hh:mm:ss"),4,2)+Q15)-FLOOR((MID(TEXT(L16,"hh:mm:ss"),4,2)+Q15),15))>ABS((MID(TEXT(L16,"hh:mm:ss"),4,2)+Q15)-CEILING((MID(TEXT(L16,"hh:mm:ss"),4,2)+Q15),15)),CEILING((MID(TEXT(L16,"hh:mm:ss"),4,2)+Q15),15),FLOOR((MID(TEXT(L16,"hh:mm:ss"),4,2)+Q15),15)) -> -4 | T16: =T15-P16 -> 4.2118056 | V16: 0.23958333 | W16: 45266 | Y16: =IF(M16="O",P16 - AA16,"0:00:00") -> 0.28125 | Z16: =IF(M16="C",P16,"0:00:00") -> 0:00:00 | AA16: =IF(P16="M",Q16-P16,"0:00:00") -> 0:00:00 | AB16: =SUM(Y16:Z16) -> 0.28125 | AC16: 0.23958333 | AD16: =V16=AC16 -> TRUE
A17: 46184 | B17: 0.31458333 | C17: 0.50208333 | D17: 0.51597222 | I17: 0.64583333 | J17: 0 | K17: =IF((D17-C17)<=$F$2,0,(D17-C17)-$F$2) -> 0 | L17: =(I17-B17)-K17-(H17-G17)-J17 -> 0.33125 | M17: C | P17: =MROUND(L17,"0:15") -> 0.33333333 | Q17: =VALUE(MID(TEXT(L17,"hh:mm:ss"),4,2)+Q16)-IF(ABS((MID(TEXT(L17,"hh:mm:ss"),4,2)+Q16)-FLOOR((MID(TEXT(L17,"hh:mm:ss"),4,2)+Q16),15))>ABS((MID(TEXT(L17,"hh:mm:ss"),4,2)+Q16)-CEILING((MID(TEXT(L17,"hh:mm:ss"),4,2)+Q16),15)),CEILING((MID(TEXT(L17,"hh:mm:ss"),4,2)+Q16),15),FLOOR((MID(TEXT(L17,"hh:mm:ss"),4,2)+Q16),15)) -> -7 | T17: =T16-P17 -> 3.8784722 | V17: 0 | W17: 45267 | Y17: =IF(M17="O",P17 - AA17,"0:00:00") -> 0:00:00 | Z17: =IF(M17="C",P17,"0:00:00") -> 0.33333333 | AA17: =IF(P17="M",Q17-P17,"0:00:00") -> 0:00:00 | AB17: =SUM(Y17:Z17) -> 0.33333333 | AC17: 0 | AD17: =V17=AC17 -> TRUE
A18: 46185 | B18: 0.31041667 | C18: 0.53472222 | D18: 0.54861111 | I18: 0.65833333 | J18: 0 | K18: =IF((D18-C18)<=$F$2,0,(D18-C18)-$F$2) -> 0 | L18: =(I18-B18)-K18-(H18-G18)-J18 -> 0.34791667 | M18: C | P18: =MROUND(L18,"0:15") -> 0.34375 | Q18: =VALUE(MID(TEXT(L18,"hh:mm:ss"),4,2)+Q17)-IF(ABS((MID(TEXT(L18,"hh:mm:ss"),4,2)+Q17)-FLOOR((MID(TEXT(L18,"hh:mm:ss"),4,2)+Q17),15))>ABS((MID(TEXT(L18,"hh:mm:ss"),4,2)+Q17)-CEILING((MID(TEXT(L18,"hh:mm:ss"),4,2)+Q17),15)),CEILING((MID(TEXT(L18,"hh:mm:ss"),4,2)+Q17),15),FLOOR((MID(TEXT(L18,"hh:mm:ss"),4,2)+Q17),15)) -> -1 | T18: =T17-L18 -> 3.5305556 | V18: 0 | W18: 45268 | Y18: =IF(M18="O",P18 - AA18,"0:00:00") -> 0:00:00 | Z18: =IF(M18="C",P18,"0:00:00") -> 0.34375 | AA18: =IF(P18="M",Q18-P18,"0:00:00") -> 0:00:00 | AB18: =SUM(Y18:Z18) -> 0.34375 | AC18: 0 | AD18: =V18=AC18 -> TRUE
A19: Semana 2 | L19: =SUM(L14:L18) -> 1.6645833 | P19: =SUM(P14:P18) -> 1.6666667 | W19: Semana 2
Q20: =Q18 -> -1
A21: 46188 | B21: 0.30138889 | C21: 0.48888889 | D21: 0.50277778 | I21: 0.59444444 | J21: 0 | K21: =IF((D21-C21)<=$F$2,0,(D21-C21)-$F$2) -> 0 | L21: =(I21-B21)-K21-(H21-G21)-J21 -> 0.29305556 | M21: O | P21: =MROUND(L21,"0:15") -> 0.29166667 | Q21: =VALUE(MID(TEXT(L21,"hh:mm:ss"),4,2)+Q20)-IF(ABS((MID(TEXT(L21,"hh:mm:ss"),4,2)+Q20)-FLOOR((MID(TEXT(L21,"hh:mm:ss"),4,2)+Q20),15))>ABS((MID(TEXT(L21,"hh:mm:ss"),4,2)+Q20)-CEILING((MID(TEXT(L21,"hh:mm:ss"),4,2)+Q20),15)),CEILING((MID(TEXT(L21,"hh:mm:ss"),4,2)+Q20),15),FLOOR((MID(TEXT(L21,"hh:mm:ss"),4,2)+Q20),15)) -> 1 | T21: =T18-L21 -> 3.2375 | V21: 0.36458333 | W21: 45271 | Y21: =IF(M21="O",P21 - AA21,"0:00:00") -> 0.29166667 | Z21: =IF(M21="C",P21,"0:00:00") -> 0:00:00 | AA21: =IF(P21="M",Q21-P21,"0:00:00") -> 0:00:00 | AB21: =SUM(Y21:Z21) -> 0.29166667 | AC21: 0.36458333 | AD21: =V21=AC21 -> TRUE
A22: 46189 | B22: 0.30555556 | C22: 0.5 | D22: 0.51388889 | I22: 0.64027778 | J22: 0 | K22: =IF((D22-C22)<=$F$2,0,(D22-C22)-$F$2) -> 6.2450045e-17 | L22: =(I22-B22)-K22-(H22-G22)-J22 -> 0.33472222 | M22: C | P22: =MROUND(L22,"0:15") -> 0.33333333 | Q22: =VALUE(MID(TEXT(L22,"hh:mm:ss"),4,2)+Q21)-IF(ABS((MID(TEXT(L22,"hh:mm:ss"),4,2)+Q21)-FLOOR((MID(TEXT(L22,"hh:mm:ss"),4,2)+Q21),15))>ABS((MID(TEXT(L22,"hh:mm:ss"),4,2)+Q21)-CEILING((MID(TEXT(L22,"hh:mm:ss"),4,2)+Q21),15)),CEILING((MID(TEXT(L22,"hh:mm:ss"),4,2)+Q21),15),FLOOR((MID(TEXT(L22,"hh:mm:ss"),4,2)+Q21),15)) -> 3 | T22: =T21-L22 -> 2.9027778 | V22: 0.36458333 | W22: 45272 | Y22: =IF(M22="O",P22 - AA22,"0:00:00") -> 0:00:00 | Z22: =IF(M22="C",P22,"0:00:00") -> 0.33333333 | AA22: =IF(P22="M",Q22-P22,"0:00:00") -> 0:00:00 | AB22: =SUM(Y22:Z22) -> 0.33333333 | AC22: 0.36458333 | AD22: =V22=AC22 -> TRUE
A23: 46190 | B23: 0.30972222 | C23: 0.48125 | D23: 0.49513889 | I23: 0.60208333 | J23: 0 | K23: =IF((D23-C23)<=$F$2,0,(D23-C23)-$F$2) -> 0 | L23: =(I23-B23)-K23-(H23-G23)-J23 -> 0.29236111 | M23: O | P23: =MROUND(L23,"0:15") -> 0.29166667 | Q23: =VALUE(MID(TEXT(L23,"hh:mm:ss"),4,2)+Q22)-IF(ABS((MID(TEXT(L23,"hh:mm:ss"),4,2)+Q22)-FLOOR((MID(TEXT(L23,"hh:mm:ss"),4,2)+Q22),15))>ABS((MID(TEXT(L23,"hh:mm:ss"),4,2)+Q22)-CEILING((MID(TEXT(L23,"hh:mm:ss"),4,2)+Q22),15)),CEILING((MID(TEXT(L23,"hh:mm:ss"),4,2)+Q22),15),FLOOR((MID(TEXT(L23,"hh:mm:ss"),4,2)+Q22),15)) -> 4 | T23: =T22-L23 -> 2.6104167 | V23: 0.45833333 | W23: 45273 | Y23: =IF(M23="O",P23 - AA23,"0:00:00") -> 0.29166667 | Z23: =IF(M23="C",P23,"0:00:00") -> 0:00:00 | AA23: =IF(P23="M",Q23-P23,"0:00:00") -> 0:00:00 | AB23: =SUM(Y23:Z23) -> 0.29166667 | AC23: 0.45833333 | AD23: =V23=AC23 -> TRUE
A24: 46191 | B24: 0.35416667 | C24: 0.50833333 | D24: 0.52222222 | I24: 0.66597222 | J24: 0 | K24: =IF((D24-C24)<=$F$2,0,(D24-C24)-$F$2) -> 6.2450045e-17 | L24: =(I24-B24)-K24-(H24-G24)-J24 -> 0.31180556 | M24: C | P24: =MROUND(L24,"0:15") -> 0.3125 | Q24: =VALUE(MID(TEXT(L24,"hh:mm:ss"),4,2)+Q23)-IF(ABS((MID(TEXT(L24,"hh:mm:ss"),4,2)+Q23)-FLOOR((MID(TEXT(L24,"hh:mm:ss"),4,2)+Q23),15))>ABS((MID(TEXT(L24,"hh:mm:ss"),4,2)+Q23)-CEILING((MID(TEXT(L24,"hh:mm:ss"),4,2)+Q23),15)),CEILING((MID(TEXT(L24,"hh:mm:ss"),4,2)+Q23),15),FLOOR((MID(TEXT(L24,"hh:mm:ss"),4,2)+Q23),15)) -> 3 | T24: =T23-L24 -> 2.2986111 | V24: 0.32291667 | W24: 45274 | Y24: =IF(M24="O",P24 - AA24,"0:00:00") -> 0:00:00 | Z24: =IF(M24="C",P24,"0:00:00") -> 0.3125 | AA24: =IF(P24="M",Q24-P24,"0:00:00") -> 0:00:00 | AB24: =SUM(Y24:Z24) -> 0.3125 | AC24: 0.32291667 | AD24: =V24=AC24 -> TRUE
A25: 46192 | B25: 0.30069444 | C25: 0.54166667 | D25: 0.54513889 | I25: 0.59236111 | J25: 0 | K25: =IF((D25-C25)<=$F$2,0,(D25-C25)-$F$2) -> 0 | L25: =(I25-B25)-K25-(H25-G25)-J25 -> 0.29166667 | M25: C | P25: =MROUND(L25,"0:15") -> 0.29166667 | Q25: =VALUE(MID(TEXT(L25,"hh:mm:ss"),4,2)+Q24)-IF(ABS((MID(TEXT(L25,"hh:mm:ss"),4,2)+Q24)-FLOOR((MID(TEXT(L25,"hh:mm:ss"),4,2)+Q24),15))>ABS((MID(TEXT(L25,"hh:mm:ss"),4,2)+Q24)-CEILING((MID(TEXT(L25,"hh:mm:ss"),4,2)+Q24),15)),CEILING((MID(TEXT(L25,"hh:mm:ss"),4,2)+Q24),15),FLOOR((MID(TEXT(L25,"hh:mm:ss"),4,2)+Q24),15)) -> 3 | T25: =T24-L25 -> 2.0069444 | V25: 0.36458333 | W25: 45275 | Y25: =IF(M25="O",P25 - AA25,"0:00:00") -> 0:00:00 | Z25: =IF(M25="C",P25,"0:00:00") -> 0.29166667 | AA25: =IF(P25="M",Q25-P25,"0:00:00") -> 0:00:00 | AB25: =SUM(Y25:Z25) -> 0.29166667 | AC25: 0.36458333 | AD25: =V25=AC25 -> TRUE
A26: Semana 3 | L26: =SUM(L21:L25) -> 1.5236111 | P26: =SUM(P21:P25) -> 1.5208333 | W26: Semana 3
Q27: =Q25 -> 3
A28: 46195 | B28: 0.30277778 | C28: 0.49583333 | D28: 0.51041667 | I28: 0.58472222 | J28: 0 | K28: =IF((D28-C28)<=$F$2,0,(D28-C28)-$F$2) -> 0.00069444444 | L28: =(I28-B28)-K28-(H28-G28)-J28 -> 0.28125 | M28: O | P28: =MROUND(L28,"0:15") -> 0.28125 | Q28: =VALUE(MID(TEXT(L28,"hh:mm:ss"),4,2)+Q27)-IF(ABS((MID(TEXT(L28,"hh:mm:ss"),4,2)+Q27)-FLOOR((MID(TEXT(L28,"hh:mm:ss"),4,2)+Q27),15))>ABS((MID(TEXT(L28,"hh:mm:ss"),4,2)+Q27)-CEILING((MID(TEXT(L28,"hh:mm:ss"),4,2)+Q27),15)),CEILING((MID(TEXT(L28,"hh:mm:ss"),4,2)+Q27),15),FLOOR((MID(TEXT(L28,"hh:mm:ss"),4,2)+Q27),15)) -> 3 | T28: =T25-L28 -> 1.7256944 | V28: 0.30208333 | W28: 45278 | Y28: =IF(M28="O",P28 - AA28,"0:00:00") -> 0.28125 | Z28: =IF(M28="C",P28,"0:00:00") -> 0:00:00 | AA28: =IF(P28="M",Q28-P28,"0:00:00") -> 0:00:00 | AB28: =SUM(Y28:Z28) -> 0.28125 | AC28: 0.30208333 | AD28: =V28=AC28 -> TRUE
A29: 46196 | B29: 0.35555556 | C29: 0.51805556 | D29: 0.53194444 | I29: 0.65763889 | J29: 0 | K29: =IF((D29-C29)<=$F$2,0,(D29-C29)-$F$2) -> 0 | L29: =(I29-B29)-K29-(H29-G29)-J29 -> 0.30208333 | M29: C | P29: =MROUND(L29,"0:15") -> 0.30208333 | Q29: =VALUE(MID(TEXT(L29,"hh:mm:ss"),4,2)+Q28)-IF(ABS((MID(TEXT(L29,"hh:mm:ss"),4,2)+Q28)-FLOOR((MID(TEXT(L29,"hh:mm:ss"),4,2)+Q28),15))>ABS((MID(TEXT(L29,"hh:mm:ss"),4,2)+Q28)-CEILING((MID(TEXT(L29,"hh:mm:ss"),4,2)+Q28),15)),CEILING((MID(TEXT(L29,"hh:mm:ss"),4,2)+Q28),15),FLOOR((MID(TEXT(L29,"hh:mm:ss"),4,2)+Q28),15)) -> 3 | T29: =T28-L29 -> 1.4236111 | V29: 0 | W29: 45279 | Y29: =IF(M29="O",P29 - AA29,"0:00:00") -> 0:00:00 | Z29: =IF(M29="C",P29,"0:00:00") -> 0.30208333 | AA29: =IF(P29="M",Q29-P29,"0:00:00") -> 0:00:00 | AB29: =SUM(Y29:Z29) -> 0.30208333 | AC29: 0.21875 | AD29: =V29=AC29 -> FALSE
A30: 46197 | B30: 0.30208333 | C30: 0.50555556 | D30: 0.51944444 | I30: 0.61458333 | J30: 0 | K30: =IF((D30-C30)<=$F$2,0,(D30-C30)-$F$2) -> 6.2450045e-17 | L30: =(I30-B30)-K30-(H30-G30)-J30 -> 0.3125 | M30: O | P30: =MROUND(L30,"0:15") -> 0.3125 | Q30: =VALUE(MID(TEXT(L30,"hh:mm:ss"),4,2)+Q29)-IF(ABS((MID(TEXT(L30,"hh:mm:ss"),4,2)+Q29)-FLOOR((MID(TEXT(L30,"hh:mm:ss"),4,2)+Q29),15))>ABS((MID(TEXT(L30,"hh:mm:ss"),4,2)+Q29)-CEILING((MID(TEXT(L30,"hh:mm:ss"),4,2)+Q29),15)),CEILING((MID(TEXT(L30,"hh:mm:ss"),4,2)+Q29),15),FLOOR((MID(TEXT(L30,"hh:mm:ss"),4,2)+Q29),15)) -> 3 | T30: =T29-L30 -> 1.1111111 | V30: 0.35416667 | W30: 45280 | Y30: =IF(M30="O",P30 - AA30,"0:00:00") -> 0.3125 | Z30: =IF(M30="C",P30,"0:00:00") -> 0:00:00 | AA30: =IF(P30="M",Q30-P30,"0:00:00") -> 0:00:00 | AB30: =SUM(Y30:Z30) -> 0.3125 | AC30: 0.30208333 | AD30: =V30=AC30 -> FALSE
A31: 46198 | B31: 0.30625 | C31: 0.43888889 | D31: 0.45277778 | I31: 0.59652778 | J31: 0 | K31: =IF((D31-C31)<=$F$2,0,(D31-C31)-$F$2) -> 0 | L31: =(I31-B31)-K31-(H31-G31)-J31 -> 0.29027778 | M31: C | P31: =MROUND(L31,"0:15") -> 0.29166667 | Q31: =VALUE(MID(TEXT(L31,"hh:mm:ss"),4,2)+Q30)-IF(ABS((MID(TEXT(L31,"hh:mm:ss"),4,2)+Q30)-FLOOR((MID(TEXT(L31,"hh:mm:ss"),4,2)+Q30),15))>ABS((MID(TEXT(L31,"hh:mm:ss"),4,2)+Q30)-CEILING((MID(TEXT(L31,"hh:mm:ss"),4,2)+Q30),15)),CEILING((MID(TEXT(L31,"hh:mm:ss"),4,2)+Q30),15),FLOOR((MID(TEXT(L31,"hh:mm:ss"),4,2)+Q30),15)) -> 1 | T31: =T30-L31 -> 0.82083333 | V31: 0.41666667 | W31: 45281 | Y31: =IF(M31="O",P31 - AA31,"0:00:00") -> 0:00:00 | Z31: =IF(M31="C",P31,"0:00:00") -> 0.29166667 | AA31: =IF(P31="M",Q31-P31,"0:00:00") -> 0:00:00 | AB31: =SUM(Y31:Z31) -> 0.29166667 | AC31: 0.30208333 | AD31: =V31=AC31 -> FALSE
A32: 46199 | B32: 0.31111111 | C32: 0.50069444 | D32: 0.51388889 | I32: 0.60277778 | J32: 0 | K32: =IF((D32-C32)<=$F$2,0,(D32-C32)-$F$2) -> 0 | L32: =(I32-B32)-K32-(H32-G32)-J32 -> 0.29166667 | M32: C | P32: =MROUND(L32,"0:15") -> 0.29166667 | Q32: =VALUE(MID(TEXT(L32,"hh:mm:ss"),4,2)+Q31)-IF(ABS((MID(TEXT(L32,"hh:mm:ss"),4,2)+Q31)-FLOOR((MID(TEXT(L32,"hh:mm:ss"),4,2)+Q31),15))>ABS((MID(TEXT(L32,"hh:mm:ss"),4,2)+Q31)-CEILING((MID(TEXT(L32,"hh:mm:ss"),4,2)+Q31),15)),CEILING((MID(TEXT(L32,"hh:mm:ss"),4,2)+Q31),15),FLOOR((MID(TEXT(L32,"hh:mm:ss"),4,2)+Q31),15)) -> 1 | T32: =T31-L32 -> 0.52916667 | V32: 0.35416667 | W32: 45282 | Y32: =IF(M32="O",P32 - AA32,"0:00:00") -> 0:00:00 | Z32: =IF(M32="C",P32,"0:00:00") -> 0.29166667 | AA32: =IF(P32="M",Q32-P32,"0:00:00") -> 0:00:00 | AB32: =SUM(Y32:Z32) -> 0.29166667 | AC32: 0.30208333 | AD32: =V32=AC32 -> FALSE
A33: Semana 4 | L33: =SUM(L28:L32) -> 1.4777778 | P33: =SUM(P28:P32) -> 1.4791667 | W33: Semana 4
Q34: =Q32 -> 1
A35: 46202 | B35: 0.29861111 | C35: 0.46111111 | D35: 0.47430556 | I35: 0.60555556 | J35: 0 | K35: =IF((D35-C35)<=$F$2,0,(D35-C35)-$F$2) -> 0 | L35: =(I35-B35)-K35-(H35-G35)-J35 -> 0.30694444 | M35: O | P35: =MROUND(L35,"0:15") -> 0.30208333 | Q35: =VALUE(MID(TEXT(L35,"hh:mm:ss"),4,2)+Q34)-IF(ABS((MID(TEXT(L35,"hh:mm:ss"),4,2)+Q34)-FLOOR((MID(TEXT(L35,"hh:mm:ss"),4,2)+Q34),15))>ABS((MID(TEXT(L35,"hh:mm:ss"),4,2)+Q34)-CEILING((MID(TEXT(L35,"hh:mm:ss"),4,2)+Q34),15)),CEILING((MID(TEXT(L35,"hh:mm:ss"),4,2)+Q34),15),FLOOR((MID(TEXT(L35,"hh:mm:ss"),4,2)+Q34),15)) -> -7 | T35: =T32-L35 -> 0.22222222 | V35: 0.33333333 | W35: 45285 | Y35: =IF(M35="O",P35 - AA35,"0:00:00") -> 0.30208333 | Z35: =IF(M35="C",P35,"0:00:00") -> 0:00:00 | AA35: =IF(P35="M",Q35-P35,"0:00:00") -> 0:00:00 | AB35: =SUM(Y35:Z35) -> 0.30208333 | AC35: 0.33333333 | AD35: =V35=AC35 -> TRUE
A36: 46203 | B36: 0.35625 | C36: 0.53680556 | D36: 0.55069444 | I36: 0.66388889 | J36: 0 | K36: 0 | L36: =(I36-B36)-K36-(H36-G36)-J36 -> 0.30763889 | M36: C | P36: =MROUND(L36,"0:15") -> 0.3125 | Q36: =VALUE(MID(TEXT(L36,"hh:mm:ss"),4,2)+Q35)-IF(ABS((MID(TEXT(L36,"hh:mm:ss"),4,2)+Q35)-FLOOR((MID(TEXT(L36,"hh:mm:ss"),4,2)+Q35),15))>ABS((MID(TEXT(L36,"hh:mm:ss"),4,2)+Q35)-CEILING((MID(TEXT(L36,"hh:mm:ss"),4,2)+Q35),15)),CEILING((MID(TEXT(L36,"hh:mm:ss"),4,2)+Q35),15),FLOOR((MID(TEXT(L36,"hh:mm:ss"),4,2)+Q35),15)) -> 1 | T36: =T35-L36 -> -0.085416667 | V36: 0.45833333 | W36: 45286 | Y36: =IF(M36="O",P36 - AA36,"0:00:00") -> 0:00:00 | Z36: =IF(M36="C",P36,"0:00:00") -> 0.3125 | AA36: =IF(P36="M",Q36-P36,"0:00:00") -> 0:00:00 | AB36: =SUM(Y36:Z36) -> 0.3125 | AC36: 0.45833333 | AD36: =V36=AC36 -> TRUE
P37: =TIME(MID(TEXT(L37,"hh:mm:ss"),1,2), IF(ABS((MID(TEXT(L37,"hh:mm:ss"),4,2)+Q36)-FLOOR((MID(TEXT(L37,"hh:mm:ss"),4,2)+Q36),15))>=ABS((MID(TEXT(L37,"hh:mm:ss"),4,2)+Q36)-CEILING((MID(TEXT(L37,"hh:mm:ss"),4,2)+Q36),15)),CEILING((MID(TEXT(L37,"hh:mm:ss"),4,2)+Q36),15),FLOOR((MID(TEXT(L37,"hh:mm:ss"),4,2)+Q36),15)), MID(TEXT(L37,"hh:mm:ss"),7,2)) -> 0 | Q37: =VALUE(MID(TEXT(L37,"hh:mm:ss"),4,2)+Q36)-IF(ABS((MID(TEXT(L37,"hh:mm:ss"),4,2)+Q36)-FLOOR((MID(TEXT(L37,"hh:mm:ss"),4,2)+Q36),15))>ABS((MID(TEXT(L37,"hh:mm:ss"),4,2)+Q36)-CEILING((MID(TEXT(L37,"hh:mm:ss"),4,2)+Q36),15)),CEILING((MID(TEXT(L37,"hh:mm:ss"),4,2)+Q36),15),FLOOR((MID(TEXT(L37,"hh:mm:ss"),4,2)+Q36),15)) -> 1 | T37: =T36-L37 -> -0.085416667 | V37: 0.33333333 | W37: 45287 | Y37: =IF(M37="O",P37 - AA37,"0:00:00") -> 0:00:00 | Z37: =IF(M37="C",P37,"0:00:00") -> 0:00:00 | AA37: =IF(P37="M",Q37-P37,"0:00:00") -> 0:00:00 | AB37: =SUM(Y37:Z37) -> 0 | AC37: 0.33333333 | AD37: =V37=AC37 -> TRUE
P38: =TIME(MID(TEXT(L38,"hh:mm:ss"),1,2), IF(ABS((MID(TEXT(L38,"hh:mm:ss"),4,2)+Q37)-FLOOR((MID(TEXT(L38,"hh:mm:ss"),4,2)+Q37),15))>=ABS((MID(TEXT(L38,"hh:mm:ss"),4,2)+Q37)-CEILING((MID(TEXT(L38,"hh:mm:ss"),4,2)+Q37),15)),CEILING((MID(TEXT(L38,"hh:mm:ss"),4,2)+Q37),15),FLOOR((MID(TEXT(L38,"hh:mm:ss"),4,2)+Q37),15)), MID(TEXT(L38,"hh:mm:ss"),7,2)) -> 0 | Q38: =VALUE(MID(TEXT(L38,"hh:mm:ss"),4,2)+Q37)-IF(ABS((MID(TEXT(L38,"hh:mm:ss"),4,2)+Q37)-FLOOR((MID(TEXT(L38,"hh:mm:ss"),4,2)+Q37),15))>ABS((MID(TEXT(L38,"hh:mm:ss"),4,2)+Q37)-CEILING((MID(TEXT(L38,"hh:mm:ss"),4,2)+Q37),15)),CEILING((MID(TEXT(L38,"hh:mm:ss"),4,2)+Q37),15),FLOOR((MID(TEXT(L38,"hh:mm:ss"),4,2)+Q37),15)) -> 1 | T38: =T37-L38 -> -0.085416667 | V38: 0.45833333 | W38: 45288 | Y38: =IF(M38="O",P38 - AA38,"0:00:00") -> 0:00:00 | Z38: =IF(M38="C",P38,"0:00:00") -> 0:00:00 | AA38: =IF(P38="M",Q38-P38,"0:00:00") -> 0:00:00 | AB38: =SUM(Y38:Z38) -> 0 | AC38: 0.45833333 | AD38: =V38=AC38 -> TRUE
P39: =TIME(MID(TEXT(L39,"hh:mm:ss"),1,2), IF(ABS((MID(TEXT(L39,"hh:mm:ss"),4,2)+Q38)-FLOOR((MID(TEXT(L39,"hh:mm:ss"),4,2)+Q38),15))>=ABS((MID(TEXT(L39,"hh:mm:ss"),4,2)+Q38)-CEILING((MID(TEXT(L39,"hh:mm:ss"),4,2)+Q38),15)),CEILING((MID(TEXT(L39,"hh:mm:ss"),4,2)+Q38),15),FLOOR((MID(TEXT(L39,"hh:mm:ss"),4,2)+Q38),15)), MID(TEXT(L39,"hh:mm:ss"),7,2)) -> 0 | Q39: =VALUE(MID(TEXT(L39,"hh:mm:ss"),4,2)+Q38)-IF(ABS((MID(TEXT(L39,"hh:mm:ss"),4,2)+Q38)-FLOOR((MID(TEXT(L39,"hh:mm:ss"),4,2)+Q38),15))>ABS((MID(TEXT(L39,"hh:mm:ss"),4,2)+Q38)-CEILING((MID(TEXT(L39,"hh:mm:ss"),4,2)+Q38),15)),CEILING((MID(TEXT(L39,"hh:mm:ss"),4,2)+Q38),15),FLOOR((MID(TEXT(L39,"hh:mm:ss"),4,2)+Q38),15)) -> 1 | T39: =T38-L39 -> -0.085416667 | W39: 45289 | Y39: =IF(M39="O",P39 - AA39,"0:00:00") -> 0:00:00 | Z39: =IF(M39="C",P39,"0:00:00") -> 0:00:00 | AA39: =IF(P39="M",Q39-P39,"0:00:00") -> 0:00:00 | AB39: =SUM(Y39:Z39) -> 0
A40: Semana 5 | L40: =SUM(L35:L39) -> 0.61458333 | P40: =SUM(P35:P39) -> 0.61458333 | W40: Semana 5
...

Sheet Julio
A1: Empresa: | B1: IZERTIS | E1: Tiempo min comida | F1: 0.020833333 | I1: Dias Mes: | J1: 22
A2: Nombre: | E2: Tiempo desayuno | F2: 0.013888889 | I2: Horas / Día: | J2: 0.29166667
A3: Mes: | B3: 46204 | E3: % R.Domic. | F3: 50 | I3: Días R.Dom: | J3: 8
N4: Teletrabajo tardes MIXTO
A5: Día | B5: ENTRADA | C5: Salida Desay | D5: Entrada Desay | E5: Salida Comida | F5: Entrada Comida | G5: Hora Salida | H5: Hora Entrada | I5: SALIDA | J5: Total Comida | K5: Total Desayuno | L5: Total Día | M5: Ubic | N5: Entrada Comida | O5: SALIDA | T5: =C46 -> 6.4166667 | V5: JIRA | W5: Día | Y5: CONTROL TELETRABAJO | AC5: IZERTIA | AD5: IZERTIA/JIRA
Q6: 1 | Y6: OFICINA | Z6: CASA | AA6: MIXTA T. | AB6: Total
P7: =MROUND(L7,"0:15") -> 0 | Q7: =VALUE(MID(TEXT(L7,"hh:mm:ss"),4,2)+Q6)-IF(ABS((MID(TEXT(L7,"hh:mm:ss"),4,2)+Q6)-FLOOR((MID(TEXT(L7,"hh:mm:ss"),4,2)+Q6),15))>ABS((MID(TEXT(L7,"hh:mm:ss"),4,2)+Q6)-CEILING((MID(TEXT(L7,"hh:mm:ss"),4,2)+Q6),15)),CEILING((MID(TEXT(L7,"hh:mm:ss"),4,2)+Q6),15),FLOOR((MID(TEXT(L7,"hh:mm:ss"),4,2)+Q6),15)) -> 1 | T7: =T5-L7 -> 6.4166667 | V7: 0 | Y7: =IF(O7="O",V7 - AA7,"0:00:00") -> 0:00:00 | Z7: =IF(M7="C",P7,"0:00:00") -> 0:00:00 | AA7: =IF(P7="M",Q7-P7,"0:00:00") -> 0:00:00 | AB7: =SUM(Y7:Z7) -> 0 | AC7: 0
P8: =MROUND(L8,"0:15") -> 0 | Q8: =VALUE(MID(TEXT(L8,"hh:mm:ss"),4,2)+Q7)-IF(ABS((MID(TEXT(L8,"hh:mm:ss"),4,2)+Q7)-FLOOR((MID(TEXT(L8,"hh:mm:ss"),4,2)+Q7),15))>ABS((MID(TEXT(L8,"hh:mm:ss"),4,2)+Q7)-CEILING((MID(TEXT(L8,"hh:mm:ss"),4,2)+Q7),15)),CEILING((MID(TEXT(L8,"hh:mm:ss"),4,2)+Q7),15),FLOOR((MID(TEXT(L8,"hh:mm:ss"),4,2)+Q7),15)) -> 1 | T8: =T7-L8 -> 6.4166667 | V8: 0 | Y8: =IF(M8="O",P8 - AA8,"0:00:00") -> 0:00:00 | Z8: =IF(M8="C",P8,"0:00:00") -> 0:00:00 | AA8: 0 | AB8: =SUM(Y8:Z8) -> 0 | AC8: 0
A9: 46204 | B9: 0.30208333 | C9: 0.47291667 | D9: 0.48819444 | I9: 0.60902778 | J9: =F9-E9 -> 0 | K9: =IF((D9-C9)<=$F$2,0,(D9-C9)-$F$2) -> 0.0013888889 | L9: =(I9-B9)-K9-(H9-G9)-J9 -> 0.30555556 | M9: O | P9: =MROUND(L9,"0:15") -> 0.30208333 | Q9: =VALUE(MID(TEXT(L9,"hh:mm:ss"),4,2)+Q8)-IF(ABS((MID(TEXT(L9,"hh:mm:ss"),4,2)+Q8)-FLOOR((MID(TEXT(L9,"hh:mm:ss"),4,2)+Q8),15))>ABS((MID(TEXT(L9,"hh:mm:ss"),4,2)+Q8)-CEILING((MID(TEXT(L9,"hh:mm:ss"),4,2)+Q8),15)),CEILING((MID(TEXT(L9,"hh:mm:ss"),4,2)+Q8),15),FLOOR((MID(TEXT(L9,"hh:mm:ss"),4,2)+Q8),15)) -> 6 | T9: =T8-L9 -> 6.1111111 | V9: 0 | Y9: =IF(M9="O",P9 - AA9,"0:00:00") -> 0.30208333 | Z9: =IF(M9="C",P9,"0:00:00") -> 0:00:00 | AA9: =IF(P9="M",Q9-P9,"0:00:00") -> 0:00:00 | AB9: =SUM(Y9:Z9) -> 0.30208333 | AC9: 0 | AD9: =V9=AC9 -> TRUE
A10: 46205 | B10: 0.31180556 | C10: 0.49166667 | D10: 0.50555556 | I10: 0.62222222 | J10: =F10-E10 -> 0 | K10: =IF((D10-C10)<=$F$2,0,(D10-C10)-$F$2) -> 0 | L10: =(I10-B10)-K10-(H10-G10)-J10 -> 0.31041667 | M10: C | P10: =MROUND(L10,"0:15") -> 0.3125 | Q10: =VALUE(MID(TEXT(L10,"hh:mm:ss"),4,2)+Q9)-IF(ABS((MID(TEXT(L10,"hh:mm:ss"),4,2)+Q9)-FLOOR((MID(TEXT(L10,"hh:mm:ss"),4,2)+Q9),15))>ABS((MID(TEXT(L10,"hh:mm:ss"),4,2)+Q9)-CEILING((MID(TEXT(L10,"hh:mm:ss"),4,2)+Q9),15)),CEILING((MID(TEXT(L10,"hh:mm:ss"),4,2)+Q9),15),FLOOR((MID(TEXT(L10,"hh:mm:ss"),4,2)+Q9),15)) -> 3 | T10: =T9-L10 -> 5.8006944 | V10: 0.45833333 | Y10: =IF(M10="O",P10 - AA10,"0:00:00") -> 0:00:00 | Z10: =IF(M10="C",P10,"0:00:00") -> 0.3125 | AA10: =IF(P10="M",Q10-P10,"0:00:00") -> 0:00:00 | AB10: =SUM(Y10:Z10) -> 0.3125 | AC10: 0.45833333 | AD10: =V10=AC10 -> TRUE
A11: 46206 | B11: 0.31527778 | I11: 0.63888889 | J11: 0 | K11: =IF((D11-C11)<=$F$2,0,(D11-C11)-$F$2) -> 0 | L11: =(I11-B11)-K11-(H11-G11)-J11 -> 0.32361111 | M11: C | P11: =MROUND(L11,"0:15") -> 0.32291667 | Q11: =VALUE(MID(TEXT(L11,"hh:mm:ss"),4,2)+Q10)-IF(ABS((MID(TEXT(L11,"hh:mm:ss"),4,2)+Q10)-FLOOR((MID(TEXT(L11,"hh:mm:ss"),4,2)+Q10),15))>ABS((MID(TEXT(L11,"hh:mm:ss"),4,2)+Q10)-CEILING((MID(TEXT(L11,"hh:mm:ss"),4,2)+Q10),15)),CEILING((MID(TEXT(L11,"hh:mm:ss"),4,2)+Q10),15),FLOOR((MID(TEXT(L11,"hh:mm:ss"),4,2)+Q10),15)) -> 4 | T11: =T10-L11 -> 5.4770833 | V11: 0.29166667 | W11: 45261 | Y11: =IF(M11="O",P11 - AA11,"0:00:00") -> 0:00:00 | Z11: =IF(M11="C",P11,"0:00:00") -> 0.32291667 | AA11: =IF(P11="M",Q11-P11,"0:00:00") -> 0:00:00 | AB11: =SUM(Y11:Z11) -> 0.32291667 | AC11: 0.29166667 | AD11: =V11=AC11 -> TRUE
A12: Semana 1 | L12: =SUM(L7:L11) -> 0.93958333 | P12: =SUM(P7:P11) -> 0.9375 | W12: Semana 1
Q13: =Q11 -> 4
A14: 46209 | B14: 0.30625 | C14: 0.49722222 | D14: 0.51180556 | I14: 0.60763889 | J14: =F14-E14 -> 0 | K14: =IF((D14-C14)<=$F$2,0,(D14-C14)-$F$2) -> 0.00069444444 | L14: =(I14-B14)-K14-(H14-G14)-J14 -> 0.30069444 | M14: O | P14: =MROUND(L14,"0:15") -> 0.30208333 | Q14: =VALUE(MID(TEXT(L14,"hh:mm:ss"),4,2)+Q13)-IF(ABS((MID(TEXT(L14,"hh:mm:ss"),4,2)+Q13)-FLOOR((MID(TEXT(L14,"hh:mm:ss"),4,2)+Q13),15))>ABS((MID(TEXT(L14,"hh:mm:ss"),4,2)+Q13)-CEILING((MID(TEXT(L14,"hh:mm:ss"),4,2)+Q13),15)),CEILING((MID(TEXT(L14,"hh:mm:ss"),4,2)+Q13),15),FLOOR((MID(TEXT(L14,"hh:mm:ss"),4,2)+Q13),15)) -> 2 | T14: =T11-L14 -> 5.1763889 | V14: 0.30208333 | W14: 45264 | Y14: =IF(M14="O",P14 - AA14,"0:00:00") -> 0.30208333 | Z14: =IF(M14="C",P14,"0:00:00") -> 0:00:00 | AA14: =IF(P14="M",Q14-P14,"0:00:00") -> 0:00:00 | AB14: =SUM(Y14:Z14) -> 0.30208333 | AC14: 0.30208333 | AD14: =V14=AC14 -> TRUE
A15: 46210 | B15: 0.35277778 | C15: 0.50416667 | D15: 0.51527778 | I15: 0.63402778 | J15: =F15-E15 -> 0 | K15: =IF((D15-C15)<=$F$2,0,(D15-C15)-$F$2) -> 0 | L15: =(I15-B15)-K15-(H15-G15)-J15 -> 0.28125 | M15: C | P15: =MROUND(L15,"0:15") -> 0.28125 | Q15: =VALUE(MID(TEXT(L15,"hh:mm:ss"),4,2)+Q14)-IF(ABS((MID(TEXT(L15,"hh:mm:ss"),4,2)+Q14)-FLOOR((MID(TEXT(L15,"hh:mm:ss"),4,2)+Q14),15))>ABS((MID(TEXT(L15,"hh:mm:ss"),4,2)+Q14)-CEILING((MID(TEXT(L15,"hh:mm:ss"),4,2)+Q14),15)),CEILING((MID(TEXT(L15,"hh:mm:ss"),4,2)+Q14),15),FLOOR((MID(TEXT(L15,"hh:mm:ss"),4,2)+Q14),15)) -> 2 | T15: =T14-L15 -> 4.8951389 | V15: 0.25 | W15: 45265 | Y15: =IF(M15="O",P15 - AA15,"0:00:00") -> 0:00:00 | Z15: =IF(M15="C",P15,"0:00:00") -> 0.28125 | AA15: =IF(P15="M",Q15-P15,"0:00:00") -> 0:00:00 | AB15: =SUM(Y15:Z15) -> 0.28125 | AC15: 0.25 | AD15: =V15=AC15 -> TRUE
A16: 46211 | B16: 0.36736111 | C16: 0.48888889 | D16: 0.50138889 | I16: 0.66944444 | J16: =F16-E16 -> 0 | K16: =IF((D16-C16)<=$F$2,0,(D16-C16)-$F$2) -> 0 | L16: =(I16-B16)-K16-(H16-G16)-J16 -> 0.30208333 | M16: O | P16: =MROUND(L16,"0:15") -> 0.30208333 | Q16: =VALUE(MID(TEXT(L16,"hh:mm:ss"),4,2)+Q15)-IF(ABS((MID(TEXT(L16,"hh:mm:ss"),4,2)+Q15)-FLOOR((MID(TEXT(L16,"hh:mm:ss"),4,2)+Q15),15))>ABS((MID(TEXT(L16,"hh:mm:ss"),4,2)+Q15)-CEILING((MID(TEXT(L16,"hh:mm:ss"),4,2)+Q15),15)),CEILING((MID(TEXT(L16,"hh:mm:ss"),4,2)+Q15),15),FLOOR((MID(TEXT(L16,"hh:mm:ss"),4,2)+Q15),15)) -> 2 | T16: =T15-P16 -> 4.5930556 | V16: 0.23958333 | W16: 45266 | Y16: =IF(M16="O",P16 - AA16,"0:00:00") -> 0.30208333 | Z16: =IF(M16="C",P16,"0:00:00") -> 0:00:00 | AA16: =IF(P16="M",Q16-P16,"0:00:00") -> 0:00:00 | AB16: =SUM(Y16:Z16) -> 0.30208333 | AC16: 0.23958333 | AD16: =V16=AC16 -> TRUE
A17: 46212 | B17: 0.34027778 | C17: 0.54236111 | D17: 0.55625 | I17: 0.62083333 | J17: =F17-E17 -> 0 | K17: =IF((D17-C17)<=$F$2,0,(D17-C17)-$F$2) -> 0 | L17: =(I17-B17)-K17-(H17-G17)-J17 -> 0.28055556 | M17: C | P17: =MROUND(L17,"0:15") -> 0.28125 | Q17: =VALUE(MID(TEXT(L17,"hh:mm:ss"),4,2)+Q16)-IF(ABS((MID(TEXT(L17,"hh:mm:ss"),4,2)+Q16)-FLOOR((MID(TEXT(L17,"hh:mm:ss"),4,2)+Q16),15))>ABS((MID(TEXT(L17,"hh:mm:ss"),4,2)+Q16)-CEILING((MID(TEXT(L17,"hh:mm:ss"),4,2)+Q16),15)),CEILING((MID(TEXT(L17,"hh:mm:ss"),4,2)+Q16),15),FLOOR((MID(TEXT(L17,"hh:mm:ss"),4,2)+Q16),15)) -> 1 | T17: =T16-P17 -> 4.3118056 | V17: 0 | W17: 45267 | Y17: =IF(M17="O",P17 - AA17,"0:00:00") -> 0:00:00 | Z17: =IF(M17="C",P17,"0:00:00") -> 0.28125 | AA17: =IF(P17="M",Q17-P17,"0:00:00") -> 0:00:00 | AB17: =SUM(Y17:Z17) -> 0.28125 | AC17: 0 | AD17: =V17=AC17 -> TRUE
A18: 46213 | J18: 0 | K18: =IF((D18-C18)<=$F$2,0,(D18-C18)-$F$2) -> 0 | L18: =(I18-B18)-K18-(H18-G18)-J18 -> 0 | M18: C | P18: =MROUND(L18,"0:15") -> 0 | Q18: =VALUE(MID(TEXT(L18,"hh:mm:ss"),4,2)+Q17)-IF(ABS((MID(TEXT(L18,"hh:mm:ss"),4,2)+Q17)-FLOOR((MID(TEXT(L18,"hh:mm:ss"),4,2)+Q17),15))>ABS((MID(TEXT(L18,"hh:mm:ss"),4,2)+Q17)-CEILING((MID(TEXT(L18,"hh:mm:ss"),4,2)+Q17),15)),CEILING((MID(TEXT(L18,"hh:mm:ss"),4,2)+Q17),15),FLOOR((MID(TEXT(L18,"hh:mm:ss"),4,2)+Q17),15)) -> 1 | T18: =T17-L18 -> 4.3118056 | V18: 0 | W18: 45268 | Y18: =IF(M18="O",P18 - AA18,"0:00:00") -> 0:00:00 | Z18: =IF(M18="C",P18,"0:00:00") -> 0 | AA18: =IF(P18="M",Q18-P18,"0:00:00") -> 0:00:00 | AB18: =SUM(Y18:Z18) -> 0 | AC18: 0 | AD18: =V18=AC18 -> TRUE
A19: Semana 2 | L19: =SUM(L14:L18) -> 1.1645833 | P19: =SUM(P14:P18) -> 1.1666667 | W19: Semana 2
Q20: =Q18 -> 1
A21: 46216 | B21: 0.30347222 | I21: 0.59513889 | J21: =F21-E21 -> 0 | K21: =IF((D21-C21)<=$F$2,0,(D21-C21)-$F$2) -> 0 | L21: =(I21-B21)-K21-(H21-G21)-J21 -> 0.29166667 | M21: O | P21: =MROUND(L21,"0:15") -> 0.29166667 | Q21: =VALUE(MID(TEXT(L21,"hh:mm:ss"),4,2)+Q20)-IF(ABS((MID(TEXT(L21,"hh:mm:ss"),4,2)+Q20)-FLOOR((MID(TEXT(L21,"hh:mm:ss"),4,2)+Q20),15))>ABS((MID(TEXT(L21,"hh:mm:ss"),4,2)+Q20)-CEILING((MID(TEXT(L21,"hh:mm:ss"),4,2)+Q20),15)),CEILING((MID(TEXT(L21,"hh:mm:ss"),4,2)+Q20),15),FLOOR((MID(TEXT(L21,"hh:mm:ss"),4,2)+Q20),15)) -> 1 | T21: =T18-L21 -> 4.0201389 | V21: 0.36458333 | W21: 45271 | Y21: =IF(M21="O",P21 - AA21,"0:00:00") -> 0.29166667 | Z21: =IF(M21="C",P21,"0:00:00") -> 0:00:00 | AA21: =IF(P21="M",Q21-P21,"0:00:00") -> 0:00:00 | AB21: =SUM(Y21:Z21) -> 0.29166667 | AC21: 0.36458333 | AD21: =V21=AC21 -> TRUE
A22: 46217 | B22: 0.33472222 | C22: 0.54027778 | D22: 0.55416667 | I22: 0.64097222 | J22: =F22-E22 -> 0 | K22: =IF((D22-C22)<=$F$2,0,(D22-C22)-$F$2) -> 6.2450045e-17 | L22: =(I22-B22)-K22-(H22-G22)-J22 -> 0.30625 | M22: C | P22: =MROUND(L22,"0:15") -> 0.30208333 | Q22: =VALUE(MID(TEXT(L22,"hh:mm:ss"),4,2)+Q21)-IF(ABS((MID(TEXT(L22,"hh:mm:ss"),4,2)+Q21)-FLOOR((MID(TEXT(L22,"hh:mm:ss"),4,2)+Q21),15))>ABS((MID(TEXT(L22,"hh:mm:ss"),4,2)+Q21)-CEILING((MID(TEXT(L22,"hh:mm:ss"),4,2)+Q21),15)),CEILING((MID(TEXT(L22,"hh:mm:ss"),4,2)+Q21),15),FLOOR((MID(TEXT(L22,"hh:mm:ss"),4,2)+Q21),15)) -> 7 | T22: =T21-L22 -> 3.7138889 | V22: 0.36458333 | W22: 45272 | Y22: =IF(M22="O",P22 - AA22,"0:00:00") -> 0:00:00 | Z22: =IF(M22="C",P22,"0:00:00") -> 0.30208333 | AA22: =IF(P22="M",Q22-P22,"0:00:00") -> 0:00:00 | AB22: =SUM(Y22:Z22) -> 0.30208333 | AC22: 0.36458333 | AD22: =V22=AC22 -> TRUE
A23: 46218 | B23: 0.30416667 | C23: 0.48263889 | D23: 0.49652778 | I23: 0.61319444 | J23: =F23-E23 -> 0 | K23: =IF((D23-C23)<=$F$2,0,(D23-C23)-$F$2) -> 0 | L23: =(I23-B23)-K23-(H23-G23)-J23 -> 0.30902778 | M23: O | P23: =MROUND(L23,"0:15") -> 0.3125 | Q23: =VALUE(MID(TEXT(L23,"hh:mm:ss"),4,2)+Q22)-IF(ABS((MID(TEXT(L23,"hh:mm:ss"),4,2)+Q22)-FLOOR((MID(TEXT(L23,"hh:mm:ss"),4,2)+Q22),15))>ABS((MID(TEXT(L23,"hh:mm:ss"),4,2)+Q22)-CEILING((MID(TEXT(L23,"hh:mm:ss"),4,2)+Q22),15)),CEILING((MID(TEXT(L23,"hh:mm:ss"),4,2)+Q22),15),FLOOR((MID(TEXT(L23,"hh:mm:ss"),4,2)+Q22),15)) -> 2 | T23: =T22-L23 -> 3.4048611 | V23: 0.45833333 | W23: 45273 | Y23: =IF(M23="O",P23 - AA23,"0:00:00") -> 0.3125 | Z23: =IF(M23="C",P23,"0:00:00") -> 0:00:00 | AA23: =IF(P23="M",Q23-P23,"0:00:00") -> 0:00:00 | AB23: =SUM(Y23:Z23) -> 0.3125 | AC23: 0.45833333 | AD23: =V23=AC23 -> TRUE
A24: 46219 | B24: 0.30138889 | C24: 0.49375 | D24: 0.50763889 | I24: 0.62361111 | J24: =F24-E24 -> 0 | K24: =IF((D24-C24)<=$F$2,0,(D24-C24)-$F$2) -> 0 | L24: =(I24-B24)-K24-(H24-G24)-J24 -> 0.32222222 | M24: O | P24: =MROUND(L24,"0:15") -> 0.32291667 | Q24: =VALUE(MID(TEXT(L24,"hh:mm:ss"),4,2)+Q23)-IF(ABS((MID(TEXT(L24,"hh:mm:ss"),4,2)+Q23)-FLOOR((MID(TEXT(L24,"hh:mm:ss"),4,2)+Q23),15))>ABS((MID(TEXT(L24,"hh:mm:ss"),4,2)+Q23)-CEILING((MID(TEXT(L24,"hh:mm:ss"),4,2)+Q23),15)),CEILING((MID(TEXT(L24,"hh:mm:ss"),4,2)+Q23),15),FLOOR((MID(TEXT(L24,"hh:mm:ss"),4,2)+Q23),15)) -> 1 | T24: =T23-L24 -> 3.0826389 | V24: 0.32291667 | W24: 45274 | Y24: =IF(M24="O",P24 - AA24,"0:00:00") -> 0.32291667 | Z24: =IF(M24="C",P24,"0:00:00") -> 0:00:00 | AA24: =IF(P24="M",Q24-P24,"0:00:00") -> 0:00:00 | AB24: =SUM(Y24:Z24) -> 0.32291667 | AC24: 0.32291667 | AD24: =V24=AC24 -> TRUE
